2017-05-09 13:54:10,932 [Thread-24:123145422602240] [django.request:152] [base:get_response] [WARNING]- Not Found: /favicon.ico
2017-05-09 13:57:12,326 [Thread-73:123145422602240] [django.request:132] [exception:handle_uncaught_exception] [ERROR]- Internal Server Error: /order/index/
Traceback (most recent call last):
  File "/Users/VANXV/.virtualenvs/zss322/lib/python3.6/site-packages/django/core/handlers/exception.py", line 42, in inner
    response = get_response(request)
  File "/Users/VANXV/.virtualenvs/zss322/lib/python3.6/site-packages/django/core/handlers/base.py", line 187, in _get_response
    response = self.process_exception_by_middleware(e, request)
  File "/Users/VANXV/.virtualenvs/zss322/lib/python3.6/site-packages/django/core/handlers/base.py", line 185, in _get_response
    response = wrapped_callback(request, *callback_args, **callback_kwargs)
  File "/Users/VANXV/.virtualenvs/zss322/lib/python3.6/site-packages/django/views/generic/base.py", line 68, in view
    return self.dispatch(request, *args, **kwargs)
  File "/Users/VANXV/.virtualenvs/zss322/lib/python3.6/site-packages/django/contrib/auth/mixins.py", line 56, in dispatch
    return super(LoginRequiredMixin, self).dispatch(request, *args, **kwargs)
  File "/Users/VANXV/.virtualenvs/zss322/lib/python3.6/site-packages/django/views/generic/base.py", line 88, in dispatch
    return handler(request, *args, **kwargs)
  File "/Users/VANXV/PycharmProjects/zss/orders/views.py", line 38, in post
    with open(filename, 'wb+') as f:
FileNotFoundError: [Errno 2] No such file or directory: '/Users/VANXV/PycharmProjects/zss/media/1494309432.csv'
2017-05-09 18:02:51,212 [Thread-102:123145474408448] [django.request:152] [base:get_response] [WARNING]- Not Found: /favicon.ico
2017-05-10 15:39:11,297 [Thread-18:123145429213184] [django.request:152] [base:get_response] [WARNING]- Not Found: /favicon.ico
2017-05-10 21:07:47,968 [Thread-22:123145365553152] [django.request:152] [base:get_response] [WARNING]- Not Found: /favicon.ico
2017-05-11 13:20:51,111 [Thread-18:123145362890752] [django.request:152] [base:get_response] [WARNING]- Not Found: /favicon.ico
2017-05-11 13:38:27,845 [Thread-9:123145454370816] [django.request:152] [base:get_response] [WARNING]- Not Found: /welcome/goods/Good_Index_Add/
2017-05-11 14:00:40,986 [Thread-27:123145521131520] [django.request:152] [base:get_response] [WARNING]- Not Found: /welcome/good/add_good/Good_Index_Add/
2017-05-11 14:21:19,088 [Thread-34:123145475305472] [django.request:132] [exception:handle_uncaught_exception] [ERROR]- Internal Server Error: /good/shop/add_good/Good_Index_Add/
Traceback (most recent call last):
  File "/Users/VANXV/.virtualenvs/zss322/lib/python3.6/site-packages/django/core/handlers/exception.py", line 42, in inner
    response = get_response(request)
  File "/Users/VANXV/.virtualenvs/zss322/lib/python3.6/site-packages/django/core/handlers/base.py", line 198, in _get_response
    "returned None instead." % (callback.__module__, view_name)
ValueError: The view goods.views.shopsViews didn't return an HttpResponse object. It returned None instead.
2017-05-11 14:21:46,152 [Thread-14:123145544994816] [django.request:132] [exception:handle_uncaught_exception] [ERROR]- Internal Server Error: /good/shop/add_good/Good_Index_Add/
Traceback (most recent call last):
  File "/Users/VANXV/.virtualenvs/zss322/lib/python3.6/site-packages/django/core/handlers/exception.py", line 42, in inner
    response = get_response(request)
  File "/Users/VANXV/.virtualenvs/zss322/lib/python3.6/site-packages/django/core/handlers/base.py", line 198, in _get_response
    "returned None instead." % (callback.__module__, view_name)
ValueError: The view goods.views.shopsViews didn't return an HttpResponse object. It returned None instead.
2017-05-11 14:22:16,184 [Thread-18:123145544994816] [django.request:132] [exception:handle_uncaught_exception] [ERROR]- Internal Server Error: /good/shop/add_good/Good_Index_Add/
Traceback (most recent call last):
  File "/Users/VANXV/.virtualenvs/zss322/lib/python3.6/site-packages/django/core/handlers/exception.py", line 42, in inner
    response = get_response(request)
  File "/Users/VANXV/.virtualenvs/zss322/lib/python3.6/site-packages/django/core/handlers/base.py", line 198, in _get_response
    "returned None instead." % (callback.__module__, view_name)
ValueError: The view goods.views.shopsViews didn't return an HttpResponse object. It returned None instead.
2017-05-11 14:46:35,278 [Thread-54:123145526386688] [django.request:132] [exception:handle_uncaught_exception] [ERROR]- Internal Server Error: /good/shop/shop/add_good/Good_Index_Add/
Traceback (most recent call last):
  File "/Users/VANXV/.virtualenvs/zss322/lib/python3.6/site-packages/django/core/handlers/exception.py", line 42, in inner
    response = get_response(request)
  File "/Users/VANXV/.virtualenvs/zss322/lib/python3.6/site-packages/django/core/handlers/base.py", line 198, in _get_response
    "returned None instead." % (callback.__module__, view_name)
ValueError: The view goods.views.shopsViews didn't return an HttpResponse object. It returned None instead.
2017-05-11 14:47:16,456 [Thread-10:123145434845184] [django.request:132] [exception:handle_uncaught_exception] [ERROR]- Internal Server Error: /good/shop/shop/add_good/Good_Index_Add/shop/add_good/Good_Index_Add/
Traceback (most recent call last):
  File "/Users/VANXV/.virtualenvs/zss322/lib/python3.6/site-packages/django/core/handlers/exception.py", line 42, in inner
    response = get_response(request)
  File "/Users/VANXV/.virtualenvs/zss322/lib/python3.6/site-packages/django/core/handlers/base.py", line 198, in _get_response
    "returned None instead." % (callback.__module__, view_name)
ValueError: The view goods.views.shopsViews didn't return an HttpResponse object. It returned None instead.
2017-05-11 14:47:48,013 [Thread-7:123145389080576] [django.request:132] [exception:handle_uncaught_exception] [ERROR]- Internal Server Error: /good/shop/shop/add_good/Good_Index_Add/shop/add_good/Good_Index_Add/shop/add_good/Good_Index_Add/
Traceback (most recent call last):
  File "/Users/VANXV/.virtualenvs/zss322/lib/python3.6/site-packages/django/core/handlers/exception.py", line 42, in inner
    response = get_response(request)
  File "/Users/VANXV/.virtualenvs/zss322/lib/python3.6/site-packages/django/core/handlers/base.py", line 198, in _get_response
    "returned None instead." % (callback.__module__, view_name)
ValueError: The view goods.views.shopsViews didn't return an HttpResponse object. It returned None instead.
2017-05-11 14:48:09,214 [Thread-11:123145404846080] [django.request:132] [exception:handle_uncaught_exception] [ERROR]- Internal Server Error: /good/shop/shop/add_good/Good_Index_Add/
Traceback (most recent call last):
  File "/Users/VANXV/.virtualenvs/zss322/lib/python3.6/site-packages/django/core/handlers/exception.py", line 42, in inner
    response = get_response(request)
  File "/Users/VANXV/.virtualenvs/zss322/lib/python3.6/site-packages/django/core/handlers/base.py", line 198, in _get_response
    "returned None instead." % (callback.__module__, view_name)
ValueError: The view goods.views.shopsViews didn't return an HttpResponse object. It returned None instead.
2017-05-11 14:50:18,332 [Thread-10:123145388834816] [django.request:132] [exception:handle_uncaught_exception] [ERROR]- Internal Server Error: /good/shop/shop/add_good/Good_Index_Add/
Traceback (most recent call last):
  File "/Users/VANXV/.virtualenvs/zss322/lib/python3.6/site-packages/django/core/handlers/exception.py", line 42, in inner
    response = get_response(request)
  File "/Users/VANXV/.virtualenvs/zss322/lib/python3.6/site-packages/django/core/handlers/base.py", line 198, in _get_response
    "returned None instead." % (callback.__module__, view_name)
ValueError: The view goods.views.shopsViews didn't return an HttpResponse object. It returned None instead.
2017-05-11 15:01:41,817 [Thread-24:123145358557184] [django.request:152] [base:get_response] [WARNING]- Not Found: /Good_Index_Add/
2017-05-11 15:04:24,169 [Thread-7:123145553813504] [django.request:152] [base:get_response] [WARNING]- Not Found: /good
2017-05-11 15:04:33,255 [Thread-11:123145553813504] [django.request:132] [exception:handle_uncaught_exception] [ERROR]- Internal Server Error: /good/shop/good/shop/Good_Index_Add/
Traceback (most recent call last):
  File "/Users/VANXV/.virtualenvs/zss322/lib/python3.6/site-packages/django/core/handlers/exception.py", line 42, in inner
    response = get_response(request)
  File "/Users/VANXV/.virtualenvs/zss322/lib/python3.6/site-packages/django/core/handlers/base.py", line 198, in _get_response
    "returned None instead." % (callback.__module__, view_name)
ValueError: The view goods.views.shopsViews didn't return an HttpResponse object. It returned None instead.
2017-05-11 15:05:00,398 [Thread-16:123145574834176] [django.request:132] [exception:handle_uncaught_exception] [ERROR]- Internal Server Error: /good/shop/Good_Index_Add/
Traceback (most recent call last):
  File "/Users/VANXV/.virtualenvs/zss322/lib/python3.6/site-packages/django/core/handlers/exception.py", line 42, in inner
    response = get_response(request)
  File "/Users/VANXV/.virtualenvs/zss322/lib/python3.6/site-packages/django/core/handlers/base.py", line 198, in _get_response
    "returned None instead." % (callback.__module__, view_name)
ValueError: The view goods.views.shopsViews didn't return an HttpResponse object. It returned None instead.
2017-05-11 15:07:12,093 [Thread-22:123145569579008] [django.request:132] [exception:handle_uncaught_exception] [ERROR]- Internal Server Error: /good/shop/Good_Index_Add/
Traceback (most recent call last):
  File "/Users/VANXV/.virtualenvs/zss322/lib/python3.6/site-packages/django/core/handlers/exception.py", line 42, in inner
    response = get_response(request)
  File "/Users/VANXV/.virtualenvs/zss322/lib/python3.6/site-packages/django/core/handlers/base.py", line 198, in _get_response
    "returned None instead." % (callback.__module__, view_name)
ValueError: The view goods.views.shopsViews didn't return an HttpResponse object. It returned None instead.
2017-05-11 15:08:18,754 [Thread-7:123145475452928] [django.request:152] [base:get_response] [WARNING]- Not Found: /good/
2017-05-11 15:08:29,905 [Thread-13:123145475452928] [django.request:132] [exception:handle_uncaught_exception] [ERROR]- Internal Server Error: /good/shop/Good_Index_Add/
Traceback (most recent call last):
  File "/Users/VANXV/.virtualenvs/zss322/lib/python3.6/site-packages/django/core/handlers/exception.py", line 42, in inner
    response = get_response(request)
  File "/Users/VANXV/.virtualenvs/zss322/lib/python3.6/site-packages/django/core/handlers/base.py", line 198, in _get_response
    "returned None instead." % (callback.__module__, view_name)
ValueError: The view goods.views.shopsViews didn't return an HttpResponse object. It returned None instead.
2017-05-11 15:10:52,403 [Thread-14:123145475452928] [django.request:152] [base:get_response] [WARNING]- Not Found: /product/
2017-05-11 15:11:22,193 [Thread-9:123145566461952] [django.request:152] [base:get_response] [WARNING]- Not Found: /good/
2017-05-11 15:11:32,978 [Thread-15:123145555951616] [django.request:152] [base:get_response] [WARNING]- Not Found: /good/add_good
2017-05-11 15:13:22,087 [Thread-31:123145561206784] [django.request:132] [exception:handle_uncaught_exception] [ERROR]- Internal Server Error: /good/add_good/form/
Traceback (most recent call last):
  File "/Users/VANXV/.virtualenvs/zss322/lib/python3.6/site-packages/django/core/handlers/exception.py", line 42, in inner
    response = get_response(request)
  File "/Users/VANXV/.virtualenvs/zss322/lib/python3.6/site-packages/django/core/handlers/base.py", line 187, in _get_response
    response = self.process_exception_by_middleware(e, request)
  File "/Users/VANXV/.virtualenvs/zss322/lib/python3.6/site-packages/django/core/handlers/base.py", line 185, in _get_response
    response = wrapped_callback(request, *callback_args, **callback_kwargs)
  File "/Users/VANXV/.virtualenvs/zss322/lib/python3.6/site-packages/django/views/generic/base.py", line 68, in view
    return self.dispatch(request, *args, **kwargs)
  File "/Users/VANXV/.virtualenvs/zss322/lib/python3.6/site-packages/django/contrib/auth/mixins.py", line 56, in dispatch
    return super(LoginRequiredMixin, self).dispatch(request, *args, **kwargs)
  File "/Users/VANXV/.virtualenvs/zss322/lib/python3.6/site-packages/django/views/generic/base.py", line 88, in dispatch
    return handler(request, *args, **kwargs)
  File "/Users/VANXV/PycharmProjects/zss/goods/views.py", line 80, in get
    shop_id = int(self.kwargs['shop_id'])
KeyError: 'shop_id'
2017-05-11 17:44:26,737 [Thread-66:123145484136448] [django.request:152] [base:get_response] [WARNING]- Not Found: /good/
2017-05-11 17:44:43,867 [Thread-74:123145468370944] [django.request:132] [exception:handle_uncaught_exception] [ERROR]- Internal Server Error: /good/shop/Good_Index_Add/
Traceback (most recent call last):
  File "/Users/VANXV/.virtualenvs/zss322/lib/python3.6/site-packages/django/core/handlers/exception.py", line 42, in inner
    response = get_response(request)
  File "/Users/VANXV/.virtualenvs/zss322/lib/python3.6/site-packages/django/core/handlers/base.py", line 198, in _get_response
    "returned None instead." % (callback.__module__, view_name)
ValueError: The view goods.views.shopsViews didn't return an HttpResponse object. It returned None instead.
2017-05-11 17:47:21,876 [Thread-9:123145338220544] [django.request:132] [exception:handle_uncaught_exception] [ERROR]- Internal Server Error: /good/shop/GoodIndexAdd/
Traceback (most recent call last):
  File "/Users/VANXV/.virtualenvs/zss322/lib/python3.6/site-packages/django/core/handlers/exception.py", line 42, in inner
    response = get_response(request)
  File "/Users/VANXV/.virtualenvs/zss322/lib/python3.6/site-packages/django/core/handlers/base.py", line 198, in _get_response
    "returned None instead." % (callback.__module__, view_name)
ValueError: The view goods.views.shopsViews didn't return an HttpResponse object. It returned None instead.
2017-05-11 17:49:30,428 [Thread-14:123145338220544] [django.request:132] [exception:handle_uncaught_exception] [ERROR]- Internal Server Error: /good/shop/GoodIndexAdd/
Traceback (most recent call last):
  File "/Users/VANXV/.virtualenvs/zss322/lib/python3.6/site-packages/django/core/handlers/exception.py", line 42, in inner
    response = get_response(request)
  File "/Users/VANXV/.virtualenvs/zss322/lib/python3.6/site-packages/django/core/handlers/base.py", line 198, in _get_response
    "returned None instead." % (callback.__module__, view_name)
ValueError: The view goods.views.shopsViews didn't return an HttpResponse object. It returned None instead.
2017-05-11 18:04:16,745 [Thread-30:123145338220544] [django.request:132] [exception:handle_uncaught_exception] [ERROR]- Internal Server Error: /good/shop/GoodIndexAdd/
Traceback (most recent call last):
  File "/Users/VANXV/.virtualenvs/zss322/lib/python3.6/site-packages/django/core/handlers/exception.py", line 42, in inner
    response = get_response(request)
  File "/Users/VANXV/.virtualenvs/zss322/lib/python3.6/site-packages/django/core/handlers/base.py", line 198, in _get_response
    "returned None instead." % (callback.__module__, view_name)
ValueError: The view goods.views.shopsViews didn't return an HttpResponse object. It returned None instead.
2017-05-11 21:28:16,184 [Thread-9:123145509916672] [django.request:152] [base:get_response] [WARNING]- Not Found: /shop
2017-05-11 21:28:25,056 [Thread-16:123145515171840] [django.request:152] [base:get_response] [WARNING]- Not Found: /good/GoodIndexAdd/
2017-05-11 21:30:38,088 [Thread-10:123145471029248] [django.request:152] [base:get_response] [WARNING]- Not Found: /good/GoodIndexAdd/
2017-05-11 21:31:13,567 [Thread-10:123145538473984] [django.request:132] [exception:handle_uncaught_exception] [ERROR]- Internal Server Error: /good/GoodIndexAdd/
Traceback (most recent call last):
  File "/Users/VANXV/.virtualenvs/zss322/lib/python3.6/site-packages/django/core/handlers/exception.py", line 42, in inner
    response = get_response(request)
  File "/Users/VANXV/.virtualenvs/zss322/lib/python3.6/site-packages/django/core/handlers/base.py", line 187, in _get_response
    response = self.process_exception_by_middleware(e, request)
  File "/Users/VANXV/.virtualenvs/zss322/lib/python3.6/site-packages/django/core/handlers/base.py", line 185, in _get_response
    response = wrapped_callback(request, *callback_args, **callback_kwargs)
TypeError: __init__() takes 1 positional argument but 2 were given
2017-05-11 21:31:20,477 [Thread-13:123145522708480] [django.request:132] [exception:handle_uncaught_exception] [ERROR]- Internal Server Error: /good/GoodIndexAdd/
Traceback (most recent call last):
  File "/Users/VANXV/.virtualenvs/zss322/lib/python3.6/site-packages/django/core/handlers/exception.py", line 42, in inner
    response = get_response(request)
  File "/Users/VANXV/.virtualenvs/zss322/lib/python3.6/site-packages/django/core/handlers/base.py", line 187, in _get_response
    response = self.process_exception_by_middleware(e, request)
  File "/Users/VANXV/.virtualenvs/zss322/lib/python3.6/site-packages/django/core/handlers/base.py", line 185, in _get_response
    response = wrapped_callback(request, *callback_args, **callback_kwargs)
TypeError: __init__() takes 1 positional argument but 2 were given
2017-05-11 21:31:57,585 [Thread-20:123145538473984] [django.request:132] [exception:handle_uncaught_exception] [ERROR]- Internal Server Error: /good/GoodIndexAdd/
Traceback (most recent call last):
  File "/Users/VANXV/.virtualenvs/zss322/lib/python3.6/site-packages/django/core/handlers/exception.py", line 42, in inner
    response = get_response(request)
  File "/Users/VANXV/.virtualenvs/zss322/lib/python3.6/site-packages/django/core/handlers/base.py", line 187, in _get_response
    response = self.process_exception_by_middleware(e, request)
  File "/Users/VANXV/.virtualenvs/zss322/lib/python3.6/site-packages/django/core/handlers/base.py", line 185, in _get_response
    response = wrapped_callback(request, *callback_args, **callback_kwargs)
TypeError: __init__() takes 1 positional argument but 2 were given
2017-05-11 21:35:22,593 [Thread-10:123145612439552] [django.request:132] [exception:handle_uncaught_exception] [ERROR]- Internal Server Error: /good/GoodIndexAdd/
Traceback (most recent call last):
  File "/Users/VANXV/.virtualenvs/zss322/lib/python3.6/site-packages/django/core/handlers/exception.py", line 42, in inner
    response = get_response(request)
  File "/Users/VANXV/.virtualenvs/zss322/lib/python3.6/site-packages/django/core/handlers/base.py", line 187, in _get_response
    response = self.process_exception_by_middleware(e, request)
  File "/Users/VANXV/.virtualenvs/zss322/lib/python3.6/site-packages/django/core/handlers/base.py", line 185, in _get_response
    response = wrapped_callback(request, *callback_args, **callback_kwargs)
TypeError: __init__() takes 1 positional argument but 2 were given
2017-05-12 14:16:10,728 [Thread-18:123145555734528] [django.request:152] [base:get_response] [WARNING]- Not Found: /favicon.ico
2017-05-12 14:16:17,047 [Thread-32:123145555734528] [django.request:132] [exception:handle_uncaught_exception] [ERROR]- Internal Server Error: /good/GoodIndexAdd/
Traceback (most recent call last):
  File "/Users/VANXV/.virtualenvs/zss322/lib/python3.6/site-packages/django/core/handlers/exception.py", line 42, in inner
    response = get_response(request)
  File "/Users/VANXV/.virtualenvs/zss322/lib/python3.6/site-packages/django/core/handlers/base.py", line 187, in _get_response
    response = self.process_exception_by_middleware(e, request)
  File "/Users/VANXV/.virtualenvs/zss322/lib/python3.6/site-packages/django/core/handlers/base.py", line 185, in _get_response
    response = wrapped_callback(request, *callback_args, **callback_kwargs)
TypeError: __init__() takes 1 positional argument but 2 were given
2017-05-12 14:38:09,489 [Thread-6:123145419747328] [django.request:132] [exception:handle_uncaught_exception] [ERROR]- Internal Server Error: /good/GoodIndexAdd/
Traceback (most recent call last):
  File "/Users/VANXV/.virtualenvs/zss322/lib/python3.6/site-packages/django/core/handlers/exception.py", line 42, in inner
    response = get_response(request)
  File "/Users/VANXV/.virtualenvs/zss322/lib/python3.6/site-packages/django/core/handlers/base.py", line 187, in _get_response
    response = self.process_exception_by_middleware(e, request)
  File "/Users/VANXV/.virtualenvs/zss322/lib/python3.6/site-packages/django/core/handlers/base.py", line 185, in _get_response
    response = wrapped_callback(request, *callback_args, **callback_kwargs)
TypeError: __init__() takes 1 positional argument but 2 were given
2017-05-12 14:39:18,597 [Thread-12:123145414492160] [django.request:132] [exception:handle_uncaught_exception] [ERROR]- Internal Server Error: /good/GoodIndexAdd/
Traceback (most recent call last):
  File "/Users/VANXV/.virtualenvs/zss322/lib/python3.6/site-packages/django/core/handlers/exception.py", line 42, in inner
    response = get_response(request)
  File "/Users/VANXV/.virtualenvs/zss322/lib/python3.6/site-packages/django/core/handlers/base.py", line 187, in _get_response
    response = self.process_exception_by_middleware(e, request)
  File "/Users/VANXV/.virtualenvs/zss322/lib/python3.6/site-packages/django/core/handlers/base.py", line 185, in _get_response
    response = wrapped_callback(request, *callback_args, **callback_kwargs)
TypeError: __init__() takes 1 positional argument but 2 were given
2017-05-12 15:08:56,537 [Thread-15:123145371230208] [django.request:132] [exception:handle_uncaught_exception] [ERROR]- Internal Server Error: /good/GoodIndexAdd/
Traceback (most recent call last):
  File "/Users/VANXV/.virtualenvs/zss322/lib/python3.6/site-packages/django/core/handlers/exception.py", line 42, in inner
    response = get_response(request)
  File "/Users/VANXV/.virtualenvs/zss322/lib/python3.6/site-packages/django/core/handlers/base.py", line 187, in _get_response
    response = self.process_exception_by_middleware(e, request)
  File "/Users/VANXV/.virtualenvs/zss322/lib/python3.6/site-packages/django/core/handlers/base.py", line 185, in _get_response
    response = wrapped_callback(request, *callback_args, **callback_kwargs)
TypeError: __init__() takes 1 positional argument but 2 were given
2017-05-12 15:09:23,507 [Thread-12:123145598484480] [django.request:132] [exception:handle_uncaught_exception] [ERROR]- Internal Server Error: /good/GoodIndexAdd/
Traceback (most recent call last):
  File "/Users/VANXV/.virtualenvs/zss322/lib/python3.6/site-packages/django/core/handlers/exception.py", line 42, in inner
    response = get_response(request)
  File "/Users/VANXV/.virtualenvs/zss322/lib/python3.6/site-packages/django/core/handlers/base.py", line 187, in _get_response
    response = self.process_exception_by_middleware(e, request)
  File "/Users/VANXV/.virtualenvs/zss322/lib/python3.6/site-packages/django/core/handlers/base.py", line 185, in _get_response
    response = wrapped_callback(request, *callback_args, **callback_kwargs)
TypeError: __init__() takes 1 positional argument but 2 were given
2017-05-12 15:14:43,115 [Thread-21:123145572208640] [django.request:132] [exception:handle_uncaught_exception] [ERROR]- Internal Server Error: /good/GoodIndexAdd/
Traceback (most recent call last):
  File "/Users/VANXV/.virtualenvs/zss322/lib/python3.6/site-packages/django/core/handlers/exception.py", line 42, in inner
    response = get_response(request)
  File "/Users/VANXV/.virtualenvs/zss322/lib/python3.6/site-packages/django/core/handlers/base.py", line 187, in _get_response
    response = self.process_exception_by_middleware(e, request)
  File "/Users/VANXV/.virtualenvs/zss322/lib/python3.6/site-packages/django/core/handlers/base.py", line 185, in _get_response
    response = wrapped_callback(request, *callback_args, **callback_kwargs)
TypeError: __init__() takes 1 positional argument but 2 were given
2017-05-12 16:31:35,891 [Thread-8:123145396555776] [django.request:132] [exception:handle_uncaught_exception] [ERROR]- Internal Server Error: /welcome/
Traceback (most recent call last):
  File "/Users/VANXV/.virtualenvs/zss322/lib/python3.6/site-packages/django/template/base.py", line 510, in parse
    compile_func = self.tags[command]
KeyError: 'googleid'

During handling of the above exception, another exception occurred:

Traceback (most recent call last):
  File "/Users/VANXV/.virtualenvs/zss322/lib/python3.6/site-packages/django/core/handlers/exception.py", line 42, in inner
    response = get_response(request)
  File "/Users/VANXV/.virtualenvs/zss322/lib/python3.6/site-packages/django/core/handlers/base.py", line 217, in _get_response
    response = self.process_exception_by_middleware(e, request)
  File "/Users/VANXV/.virtualenvs/zss322/lib/python3.6/site-packages/django/core/handlers/base.py", line 215, in _get_response
    response = response.render()
  File "/Users/VANXV/.virtualenvs/zss322/lib/python3.6/site-packages/django/template/response.py", line 109, in render
    self.content = self.rendered_content
  File "/Users/VANXV/.virtualenvs/zss322/lib/python3.6/site-packages/django/template/response.py", line 84, in rendered_content
    template = self.resolve_template(self.template_name)
  File "/Users/VANXV/.virtualenvs/zss322/lib/python3.6/site-packages/django/template/response.py", line 66, in resolve_template
    return select_template(template, using=self.using)
  File "/Users/VANXV/.virtualenvs/zss322/lib/python3.6/site-packages/django/template/loader.py", line 48, in select_template
    return engine.get_template(template_name)
  File "/Users/VANXV/.virtualenvs/zss322/lib/python3.6/site-packages/django/template/backends/django.py", line 39, in get_template
    return Template(self.engine.get_template(template_name), self)
  File "/Users/VANXV/.virtualenvs/zss322/lib/python3.6/site-packages/django/template/engine.py", line 160, in get_template
    template, origin = self.find_template(template_name)
  File "/Users/VANXV/.virtualenvs/zss322/lib/python3.6/site-packages/django/template/engine.py", line 134, in find_template
    name, template_dirs=dirs, skip=skip,
  File "/Users/VANXV/.virtualenvs/zss322/lib/python3.6/site-packages/django/template/loaders/base.py", line 44, in get_template
    contents, origin, origin.template_name, self.engine,
  File "/Users/VANXV/.virtualenvs/zss322/lib/python3.6/site-packages/django/template/base.py", line 191, in __init__
    self.nodelist = self.compile_nodelist()
  File "/Users/VANXV/.virtualenvs/zss322/lib/python3.6/site-packages/django/template/base.py", line 233, in compile_nodelist
    return parser.parse()
  File "/Users/VANXV/.virtualenvs/zss322/lib/python3.6/site-packages/django/template/base.py", line 518, in parse
    raise self.error(token, e)
  File "/Users/VANXV/.virtualenvs/zss322/lib/python3.6/site-packages/django/template/base.py", line 516, in parse
    compiled_result = compile_func(self, token)
  File "/Users/VANXV/.virtualenvs/zss322/lib/python3.6/site-packages/django/template/loader_tags.py", line 299, in do_extends
    nodelist = parser.parse()
  File "/Users/VANXV/.virtualenvs/zss322/lib/python3.6/site-packages/django/template/base.py", line 518, in parse
    raise self.error(token, e)
  File "/Users/VANXV/.virtualenvs/zss322/lib/python3.6/site-packages/django/template/base.py", line 516, in parse
    compiled_result = compile_func(self, token)
  File "/Users/VANXV/.virtualenvs/zss322/lib/python3.6/site-packages/django/template/loader_tags.py", line 242, in do_block
    nodelist = parser.parse(('endblock',))
  File "/Users/VANXV/.virtualenvs/zss322/lib/python3.6/site-packages/django/template/base.py", line 512, in parse
    self.invalid_block_tag(token, command, parse_until)
  File "/Users/VANXV/.virtualenvs/zss322/lib/python3.6/site-packages/django/template/base.py", line 568, in invalid_block_tag
    get_text_list(["'%s'" % p for p in parse_until], 'or'),
django.template.exceptions.TemplateSyntaxError: Invalid block tag on line 11: 'googleid', expected 'endblock'. Did you forget to register or load this tag?
2017-05-12 16:31:54,354 [Thread-15:123145401810944] [django.request:132] [exception:handle_uncaught_exception] [ERROR]- Internal Server Error: /good/GoodIndexAdd/
Traceback (most recent call last):
  File "/Users/VANXV/.virtualenvs/zss322/lib/python3.6/site-packages/django/utils/datastructures.py", line 83, in __getitem__
    list_ = super(MultiValueDict, self).__getitem__(key)
KeyError: 'txtIndexAddUrl'

During handling of the above exception, another exception occurred:

Traceback (most recent call last):
  File "/Users/VANXV/.virtualenvs/zss322/lib/python3.6/site-packages/django/core/handlers/exception.py", line 42, in inner
    response = get_response(request)
  File "/Users/VANXV/.virtualenvs/zss322/lib/python3.6/site-packages/django/core/handlers/base.py", line 187, in _get_response
    response = self.process_exception_by_middleware(e, request)
  File "/Users/VANXV/.virtualenvs/zss322/lib/python3.6/site-packages/django/core/handlers/base.py", line 185, in _get_response
    response = wrapped_callback(request, *callback_args, **callback_kwargs)
  File "/Users/VANXV/.virtualenvs/zss322/lib/python3.6/site-packages/django/views/generic/base.py", line 68, in view
    return self.dispatch(request, *args, **kwargs)
  File "/Users/VANXV/.virtualenvs/zss322/lib/python3.6/site-packages/django/contrib/auth/mixins.py", line 56, in dispatch
    return super(LoginRequiredMixin, self).dispatch(request, *args, **kwargs)
  File "/Users/VANXV/.virtualenvs/zss322/lib/python3.6/site-packages/django/views/generic/base.py", line 88, in dispatch
    return handler(request, *args, **kwargs)
  File "/Users/VANXV/PycharmProjects/zss/goods/views.py", line 136, in post
    test = request.POST['txtIndexAddUrl']
  File "/Users/VANXV/.virtualenvs/zss322/lib/python3.6/site-packages/django/utils/datastructures.py", line 85, in __getitem__
    raise MultiValueDictKeyError(repr(key))
django.utils.datastructures.MultiValueDictKeyError: "'txtIndexAddUrl'"
2017-05-12 16:33:14,889 [Thread-9:123145507958784] [django.request:132] [exception:handle_uncaught_exception] [ERROR]- Internal Server Error: /good/GoodIndexAdd/
Traceback (most recent call last):
  File "/Users/VANXV/.virtualenvs/zss322/lib/python3.6/site-packages/django/utils/datastructures.py", line 83, in __getitem__
    list_ = super(MultiValueDict, self).__getitem__(key)
KeyError: 'txtIndexAddUrl'

During handling of the above exception, another exception occurred:

Traceback (most recent call last):
  File "/Users/VANXV/.virtualenvs/zss322/lib/python3.6/site-packages/django/core/handlers/exception.py", line 42, in inner
    response = get_response(request)
  File "/Users/VANXV/.virtualenvs/zss322/lib/python3.6/site-packages/django/core/handlers/base.py", line 187, in _get_response
    response = self.process_exception_by_middleware(e, request)
  File "/Users/VANXV/.virtualenvs/zss322/lib/python3.6/site-packages/django/core/handlers/base.py", line 185, in _get_response
    response = wrapped_callback(request, *callback_args, **callback_kwargs)
  File "/Users/VANXV/.virtualenvs/zss322/lib/python3.6/site-packages/django/views/generic/base.py", line 68, in view
    return self.dispatch(request, *args, **kwargs)
  File "/Users/VANXV/.virtualenvs/zss322/lib/python3.6/site-packages/django/contrib/auth/mixins.py", line 56, in dispatch
    return super(LoginRequiredMixin, self).dispatch(request, *args, **kwargs)
  File "/Users/VANXV/.virtualenvs/zss322/lib/python3.6/site-packages/django/views/generic/base.py", line 88, in dispatch
    return handler(request, *args, **kwargs)
  File "/Users/VANXV/PycharmProjects/zss/goods/views.py", line 136, in post
    test = request.POST['txtIndexAddUrl']
  File "/Users/VANXV/.virtualenvs/zss322/lib/python3.6/site-packages/django/utils/datastructures.py", line 85, in __getitem__
    raise MultiValueDictKeyError(repr(key))
django.utils.datastructures.MultiValueDictKeyError: "'txtIndexAddUrl'"
2017-05-12 16:47:10,541 [Thread-8:123145381588992] [django.request:132] [exception:handle_uncaught_exception] [ERROR]- Internal Server Error: /good/GoodIndexAdd/
Traceback (most recent call last):
  File "/Users/VANXV/.virtualenvs/zss322/lib/python3.6/site-packages/django/template/base.py", line 510, in parse
    compile_func = self.tags[command]
KeyError: 'test'

During handling of the above exception, another exception occurred:

Traceback (most recent call last):
  File "/Users/VANXV/.virtualenvs/zss322/lib/python3.6/site-packages/django/core/handlers/exception.py", line 42, in inner
    response = get_response(request)
  File "/Users/VANXV/.virtualenvs/zss322/lib/python3.6/site-packages/django/core/handlers/base.py", line 187, in _get_response
    response = self.process_exception_by_middleware(e, request)
  File "/Users/VANXV/.virtualenvs/zss322/lib/python3.6/site-packages/django/core/handlers/base.py", line 185, in _get_response
    response = wrapped_callback(request, *callback_args, **callback_kwargs)
  File "/Users/VANXV/.virtualenvs/zss322/lib/python3.6/site-packages/django/views/generic/base.py", line 68, in view
    return self.dispatch(request, *args, **kwargs)
  File "/Users/VANXV/.virtualenvs/zss322/lib/python3.6/site-packages/django/contrib/auth/mixins.py", line 56, in dispatch
    return super(LoginRequiredMixin, self).dispatch(request, *args, **kwargs)
  File "/Users/VANXV/.virtualenvs/zss322/lib/python3.6/site-packages/django/views/generic/base.py", line 88, in dispatch
    return handler(request, *args, **kwargs)
  File "/Users/VANXV/PycharmProjects/zss/goods/views.py", line 138, in post
    return render(request, 'welcome.html',{'test':test})
  File "/Users/VANXV/.virtualenvs/zss322/lib/python3.6/site-packages/django/shortcuts.py", line 30, in render
    content = loader.render_to_string(template_name, context, request, using=using)
  File "/Users/VANXV/.virtualenvs/zss322/lib/python3.6/site-packages/django/template/loader.py", line 67, in render_to_string
    template = get_template(template_name, using=using)
  File "/Users/VANXV/.virtualenvs/zss322/lib/python3.6/site-packages/django/template/loader.py", line 21, in get_template
    return engine.get_template(template_name)
  File "/Users/VANXV/.virtualenvs/zss322/lib/python3.6/site-packages/django/template/backends/django.py", line 39, in get_template
    return Template(self.engine.get_template(template_name), self)
  File "/Users/VANXV/.virtualenvs/zss322/lib/python3.6/site-packages/django/template/engine.py", line 160, in get_template
    template, origin = self.find_template(template_name)
  File "/Users/VANXV/.virtualenvs/zss322/lib/python3.6/site-packages/django/template/engine.py", line 134, in find_template
    name, template_dirs=dirs, skip=skip,
  File "/Users/VANXV/.virtualenvs/zss322/lib/python3.6/site-packages/django/template/loaders/base.py", line 44, in get_template
    contents, origin, origin.template_name, self.engine,
  File "/Users/VANXV/.virtualenvs/zss322/lib/python3.6/site-packages/django/template/base.py", line 191, in __init__
    self.nodelist = self.compile_nodelist()
  File "/Users/VANXV/.virtualenvs/zss322/lib/python3.6/site-packages/django/template/base.py", line 233, in compile_nodelist
    return parser.parse()
  File "/Users/VANXV/.virtualenvs/zss322/lib/python3.6/site-packages/django/template/base.py", line 518, in parse
    raise self.error(token, e)
  File "/Users/VANXV/.virtualenvs/zss322/lib/python3.6/site-packages/django/template/base.py", line 516, in parse
    compiled_result = compile_func(self, token)
  File "/Users/VANXV/.virtualenvs/zss322/lib/python3.6/site-packages/django/template/loader_tags.py", line 299, in do_extends
    nodelist = parser.parse()
  File "/Users/VANXV/.virtualenvs/zss322/lib/python3.6/site-packages/django/template/base.py", line 518, in parse
    raise self.error(token, e)
  File "/Users/VANXV/.virtualenvs/zss322/lib/python3.6/site-packages/django/template/base.py", line 516, in parse
    compiled_result = compile_func(self, token)
  File "/Users/VANXV/.virtualenvs/zss322/lib/python3.6/site-packages/django/template/loader_tags.py", line 242, in do_block
    nodelist = parser.parse(('endblock',))
  File "/Users/VANXV/.virtualenvs/zss322/lib/python3.6/site-packages/django/template/base.py", line 512, in parse
    self.invalid_block_tag(token, command, parse_until)
  File "/Users/VANXV/.virtualenvs/zss322/lib/python3.6/site-packages/django/template/base.py", line 568, in invalid_block_tag
    get_text_list(["'%s'" % p for p in parse_until], 'or'),
django.template.exceptions.TemplateSyntaxError: Invalid block tag on line 11: 'test', expected 'endblock'. Did you forget to register or load this tag?
2017-05-12 16:47:15,727 [Thread-10:123145386844160] [django.request:132] [exception:handle_uncaught_exception] [ERROR]- Internal Server Error: /welcome/
Traceback (most recent call last):
  File "/Users/VANXV/.virtualenvs/zss322/lib/python3.6/site-packages/django/template/base.py", line 510, in parse
    compile_func = self.tags[command]
KeyError: 'test'

During handling of the above exception, another exception occurred:

Traceback (most recent call last):
  File "/Users/VANXV/.virtualenvs/zss322/lib/python3.6/site-packages/django/core/handlers/exception.py", line 42, in inner
    response = get_response(request)
  File "/Users/VANXV/.virtualenvs/zss322/lib/python3.6/site-packages/django/core/handlers/base.py", line 217, in _get_response
    response = self.process_exception_by_middleware(e, request)
  File "/Users/VANXV/.virtualenvs/zss322/lib/python3.6/site-packages/django/core/handlers/base.py", line 215, in _get_response
    response = response.render()
  File "/Users/VANXV/.virtualenvs/zss322/lib/python3.6/site-packages/django/template/response.py", line 109, in render
    self.content = self.rendered_content
  File "/Users/VANXV/.virtualenvs/zss322/lib/python3.6/site-packages/django/template/response.py", line 84, in rendered_content
    template = self.resolve_template(self.template_name)
  File "/Users/VANXV/.virtualenvs/zss322/lib/python3.6/site-packages/django/template/response.py", line 66, in resolve_template
    return select_template(template, using=self.using)
  File "/Users/VANXV/.virtualenvs/zss322/lib/python3.6/site-packages/django/template/loader.py", line 48, in select_template
    return engine.get_template(template_name)
  File "/Users/VANXV/.virtualenvs/zss322/lib/python3.6/site-packages/django/template/backends/django.py", line 39, in get_template
    return Template(self.engine.get_template(template_name), self)
  File "/Users/VANXV/.virtualenvs/zss322/lib/python3.6/site-packages/django/template/engine.py", line 160, in get_template
    template, origin = self.find_template(template_name)
  File "/Users/VANXV/.virtualenvs/zss322/lib/python3.6/site-packages/django/template/engine.py", line 134, in find_template
    name, template_dirs=dirs, skip=skip,
  File "/Users/VANXV/.virtualenvs/zss322/lib/python3.6/site-packages/django/template/loaders/base.py", line 44, in get_template
    contents, origin, origin.template_name, self.engine,
  File "/Users/VANXV/.virtualenvs/zss322/lib/python3.6/site-packages/django/template/base.py", line 191, in __init__
    self.nodelist = self.compile_nodelist()
  File "/Users/VANXV/.virtualenvs/zss322/lib/python3.6/site-packages/django/template/base.py", line 233, in compile_nodelist
    return parser.parse()
  File "/Users/VANXV/.virtualenvs/zss322/lib/python3.6/site-packages/django/template/base.py", line 518, in parse
    raise self.error(token, e)
  File "/Users/VANXV/.virtualenvs/zss322/lib/python3.6/site-packages/django/template/base.py", line 516, in parse
    compiled_result = compile_func(self, token)
  File "/Users/VANXV/.virtualenvs/zss322/lib/python3.6/site-packages/django/template/loader_tags.py", line 299, in do_extends
    nodelist = parser.parse()
  File "/Users/VANXV/.virtualenvs/zss322/lib/python3.6/site-packages/django/template/base.py", line 518, in parse
    raise self.error(token, e)
  File "/Users/VANXV/.virtualenvs/zss322/lib/python3.6/site-packages/django/template/base.py", line 516, in parse
    compiled_result = compile_func(self, token)
  File "/Users/VANXV/.virtualenvs/zss322/lib/python3.6/site-packages/django/template/loader_tags.py", line 242, in do_block
    nodelist = parser.parse(('endblock',))
  File "/Users/VANXV/.virtualenvs/zss322/lib/python3.6/site-packages/django/template/base.py", line 512, in parse
    self.invalid_block_tag(token, command, parse_until)
  File "/Users/VANXV/.virtualenvs/zss322/lib/python3.6/site-packages/django/template/base.py", line 568, in invalid_block_tag
    get_text_list(["'%s'" % p for p in parse_until], 'or'),
django.template.exceptions.TemplateSyntaxError: Invalid block tag on line 11: 'test', expected 'endblock'. Did you forget to register or load this tag?
2017-05-12 16:47:21,388 [Thread-12:123145397354496] [django.request:132] [exception:handle_uncaught_exception] [ERROR]- Internal Server Error: /welcome/
Traceback (most recent call last):
  File "/Users/VANXV/.virtualenvs/zss322/lib/python3.6/site-packages/django/template/base.py", line 510, in parse
    compile_func = self.tags[command]
KeyError: 'test'

During handling of the above exception, another exception occurred:

Traceback (most recent call last):
  File "/Users/VANXV/.virtualenvs/zss322/lib/python3.6/site-packages/django/core/handlers/exception.py", line 42, in inner
    response = get_response(request)
  File "/Users/VANXV/.virtualenvs/zss322/lib/python3.6/site-packages/django/core/handlers/base.py", line 217, in _get_response
    response = self.process_exception_by_middleware(e, request)
  File "/Users/VANXV/.virtualenvs/zss322/lib/python3.6/site-packages/django/core/handlers/base.py", line 215, in _get_response
    response = response.render()
  File "/Users/VANXV/.virtualenvs/zss322/lib/python3.6/site-packages/django/template/response.py", line 109, in render
    self.content = self.rendered_content
  File "/Users/VANXV/.virtualenvs/zss322/lib/python3.6/site-packages/django/template/response.py", line 84, in rendered_content
    template = self.resolve_template(self.template_name)
  File "/Users/VANXV/.virtualenvs/zss322/lib/python3.6/site-packages/django/template/response.py", line 66, in resolve_template
    return select_template(template, using=self.using)
  File "/Users/VANXV/.virtualenvs/zss322/lib/python3.6/site-packages/django/template/loader.py", line 48, in select_template
    return engine.get_template(template_name)
  File "/Users/VANXV/.virtualenvs/zss322/lib/python3.6/site-packages/django/template/backends/django.py", line 39, in get_template
    return Template(self.engine.get_template(template_name), self)
  File "/Users/VANXV/.virtualenvs/zss322/lib/python3.6/site-packages/django/template/engine.py", line 160, in get_template
    template, origin = self.find_template(template_name)
  File "/Users/VANXV/.virtualenvs/zss322/lib/python3.6/site-packages/django/template/engine.py", line 134, in find_template
    name, template_dirs=dirs, skip=skip,
  File "/Users/VANXV/.virtualenvs/zss322/lib/python3.6/site-packages/django/template/loaders/base.py", line 44, in get_template
    contents, origin, origin.template_name, self.engine,
  File "/Users/VANXV/.virtualenvs/zss322/lib/python3.6/site-packages/django/template/base.py", line 191, in __init__
    self.nodelist = self.compile_nodelist()
  File "/Users/VANXV/.virtualenvs/zss322/lib/python3.6/site-packages/django/template/base.py", line 233, in compile_nodelist
    return parser.parse()
  File "/Users/VANXV/.virtualenvs/zss322/lib/python3.6/site-packages/django/template/base.py", line 518, in parse
    raise self.error(token, e)
  File "/Users/VANXV/.virtualenvs/zss322/lib/python3.6/site-packages/django/template/base.py", line 516, in parse
    compiled_result = compile_func(self, token)
  File "/Users/VANXV/.virtualenvs/zss322/lib/python3.6/site-packages/django/template/loader_tags.py", line 299, in do_extends
    nodelist = parser.parse()
  File "/Users/VANXV/.virtualenvs/zss322/lib/python3.6/site-packages/django/template/base.py", line 518, in parse
    raise self.error(token, e)
  File "/Users/VANXV/.virtualenvs/zss322/lib/python3.6/site-packages/django/template/base.py", line 516, in parse
    compiled_result = compile_func(self, token)
  File "/Users/VANXV/.virtualenvs/zss322/lib/python3.6/site-packages/django/template/loader_tags.py", line 242, in do_block
    nodelist = parser.parse(('endblock',))
  File "/Users/VANXV/.virtualenvs/zss322/lib/python3.6/site-packages/django/template/base.py", line 512, in parse
    self.invalid_block_tag(token, command, parse_until)
  File "/Users/VANXV/.virtualenvs/zss322/lib/python3.6/site-packages/django/template/base.py", line 568, in invalid_block_tag
    get_text_list(["'%s'" % p for p in parse_until], 'or'),
django.template.exceptions.TemplateSyntaxError: Invalid block tag on line 11: 'test', expected 'endblock'. Did you forget to register or load this tag?
2017-05-12 16:47:39,184 [Thread-8:123145430872064] [django.request:132] [exception:handle_uncaught_exception] [ERROR]- Internal Server Error: /welcome/
Traceback (most recent call last):
  File "/Users/VANXV/.virtualenvs/zss322/lib/python3.6/site-packages/django/template/base.py", line 510, in parse
    compile_func = self.tags[command]
KeyError: 'test'

During handling of the above exception, another exception occurred:

Traceback (most recent call last):
  File "/Users/VANXV/.virtualenvs/zss322/lib/python3.6/site-packages/django/core/handlers/exception.py", line 42, in inner
    response = get_response(request)
  File "/Users/VANXV/.virtualenvs/zss322/lib/python3.6/site-packages/django/core/handlers/base.py", line 217, in _get_response
    response = self.process_exception_by_middleware(e, request)
  File "/Users/VANXV/.virtualenvs/zss322/lib/python3.6/site-packages/django/core/handlers/base.py", line 215, in _get_response
    response = response.render()
  File "/Users/VANXV/.virtualenvs/zss322/lib/python3.6/site-packages/django/template/response.py", line 109, in render
    self.content = self.rendered_content
  File "/Users/VANXV/.virtualenvs/zss322/lib/python3.6/site-packages/django/template/response.py", line 84, in rendered_content
    template = self.resolve_template(self.template_name)
  File "/Users/VANXV/.virtualenvs/zss322/lib/python3.6/site-packages/django/template/response.py", line 66, in resolve_template
    return select_template(template, using=self.using)
  File "/Users/VANXV/.virtualenvs/zss322/lib/python3.6/site-packages/django/template/loader.py", line 48, in select_template
    return engine.get_template(template_name)
  File "/Users/VANXV/.virtualenvs/zss322/lib/python3.6/site-packages/django/template/backends/django.py", line 39, in get_template
    return Template(self.engine.get_template(template_name), self)
  File "/Users/VANXV/.virtualenvs/zss322/lib/python3.6/site-packages/django/template/engine.py", line 160, in get_template
    template, origin = self.find_template(template_name)
  File "/Users/VANXV/.virtualenvs/zss322/lib/python3.6/site-packages/django/template/engine.py", line 134, in find_template
    name, template_dirs=dirs, skip=skip,
  File "/Users/VANXV/.virtualenvs/zss322/lib/python3.6/site-packages/django/template/loaders/base.py", line 44, in get_template
    contents, origin, origin.template_name, self.engine,
  File "/Users/VANXV/.virtualenvs/zss322/lib/python3.6/site-packages/django/template/base.py", line 191, in __init__
    self.nodelist = self.compile_nodelist()
  File "/Users/VANXV/.virtualenvs/zss322/lib/python3.6/site-packages/django/template/base.py", line 233, in compile_nodelist
    return parser.parse()
  File "/Users/VANXV/.virtualenvs/zss322/lib/python3.6/site-packages/django/template/base.py", line 518, in parse
    raise self.error(token, e)
  File "/Users/VANXV/.virtualenvs/zss322/lib/python3.6/site-packages/django/template/base.py", line 516, in parse
    compiled_result = compile_func(self, token)
  File "/Users/VANXV/.virtualenvs/zss322/lib/python3.6/site-packages/django/template/loader_tags.py", line 299, in do_extends
    nodelist = parser.parse()
  File "/Users/VANXV/.virtualenvs/zss322/lib/python3.6/site-packages/django/template/base.py", line 518, in parse
    raise self.error(token, e)
  File "/Users/VANXV/.virtualenvs/zss322/lib/python3.6/site-packages/django/template/base.py", line 516, in parse
    compiled_result = compile_func(self, token)
  File "/Users/VANXV/.virtualenvs/zss322/lib/python3.6/site-packages/django/template/loader_tags.py", line 242, in do_block
    nodelist = parser.parse(('endblock',))
  File "/Users/VANXV/.virtualenvs/zss322/lib/python3.6/site-packages/django/template/base.py", line 512, in parse
    self.invalid_block_tag(token, command, parse_until)
  File "/Users/VANXV/.virtualenvs/zss322/lib/python3.6/site-packages/django/template/base.py", line 568, in invalid_block_tag
    get_text_list(["'%s'" % p for p in parse_until], 'or'),
django.template.exceptions.TemplateSyntaxError: Invalid block tag on line 11: 'test', expected 'endblock'. Did you forget to register or load this tag?
2017-05-12 17:12:58,767 [Thread-10:123145484976128] [django.request:132] [exception:handle_uncaught_exception] [ERROR]- Internal Server Error: /good/GoodIndexAdd/
Traceback (most recent call last):
  File "/Users/VANXV/.virtualenvs/zss322/lib/python3.6/site-packages/django/utils/datastructures.py", line 83, in __getitem__
    list_ = super(MultiValueDict, self).__getitem__(key)
KeyError: 'txtIndexAddUrl'

During handling of the above exception, another exception occurred:

Traceback (most recent call last):
  File "/Users/VANXV/.virtualenvs/zss322/lib/python3.6/site-packages/django/core/handlers/exception.py", line 42, in inner
    response = get_response(request)
  File "/Users/VANXV/.virtualenvs/zss322/lib/python3.6/site-packages/django/core/handlers/base.py", line 187, in _get_response
    response = self.process_exception_by_middleware(e, request)
  File "/Users/VANXV/.virtualenvs/zss322/lib/python3.6/site-packages/django/core/handlers/base.py", line 185, in _get_response
    response = wrapped_callback(request, *callback_args, **callback_kwargs)
  File "/Users/VANXV/.virtualenvs/zss322/lib/python3.6/site-packages/django/views/generic/base.py", line 68, in view
    return self.dispatch(request, *args, **kwargs)
  File "/Users/VANXV/.virtualenvs/zss322/lib/python3.6/site-packages/django/contrib/auth/mixins.py", line 56, in dispatch
    return super(LoginRequiredMixin, self).dispatch(request, *args, **kwargs)
  File "/Users/VANXV/.virtualenvs/zss322/lib/python3.6/site-packages/django/views/generic/base.py", line 88, in dispatch
    return handler(request, *args, **kwargs)
  File "/Users/VANXV/PycharmProjects/zss/goods/views.py", line 133, in post
    test = request.POST['txtIndexAddUrl']
  File "/Users/VANXV/.virtualenvs/zss322/lib/python3.6/site-packages/django/utils/datastructures.py", line 85, in __getitem__
    raise MultiValueDictKeyError(repr(key))
django.utils.datastructures.MultiValueDictKeyError: "'txtIndexAddUrl'"
2017-05-12 23:24:02,032 [Thread-9:123145342717952] [django.request:132] [exception:handle_uncaught_exception] [ERROR]- Internal Server Error: /good/GoodIndexAdd/
Traceback (most recent call last):
  File "/Users/VANXV/.virtualenvs/zss322/lib/python3.6/site-packages/django/core/handlers/exception.py", line 42, in inner
    response = get_response(request)
  File "/Users/VANXV/.virtualenvs/zss322/lib/python3.6/site-packages/django/core/handlers/base.py", line 187, in _get_response
    response = self.process_exception_by_middleware(e, request)
  File "/Users/VANXV/.virtualenvs/zss322/lib/python3.6/site-packages/django/core/handlers/base.py", line 185, in _get_response
    response = wrapped_callback(request, *callback_args, **callback_kwargs)
  File "/Users/VANXV/.virtualenvs/zss322/lib/python3.6/site-packages/django/views/generic/base.py", line 68, in view
    return self.dispatch(request, *args, **kwargs)
  File "/Users/VANXV/.virtualenvs/zss322/lib/python3.6/site-packages/django/contrib/auth/mixins.py", line 56, in dispatch
    return super(LoginRequiredMixin, self).dispatch(request, *args, **kwargs)
  File "/Users/VANXV/.virtualenvs/zss322/lib/python3.6/site-packages/django/views/generic/base.py", line 88, in dispatch
    return handler(request, *args, **kwargs)
  File "/Users/VANXV/PycharmProjects/zss/goods/views.py", line 140, in post
    babyidsave = Shop.objects.create(name=babyid, pgoods_id=babyid, keyword1=babyid, user_id=1, shop_id=1)
  File "/Users/VANXV/.virtualenvs/zss322/lib/python3.6/site-packages/django/db/models/manager.py", line 85, in manager_method
    return getattr(self.get_queryset(), name)(*args, **kwargs)
  File "/Users/VANXV/.virtualenvs/zss322/lib/python3.6/site-packages/django/db/models/query.py", line 397, in create
    obj = self.model(**kwargs)
  File "/Users/VANXV/.virtualenvs/zss322/lib/python3.6/site-packages/django/db/models/base.py", line 555, in __init__
    raise TypeError("'%s' is an invalid keyword argument for this function" % list(kwargs)[0])
TypeError: 'name' is an invalid keyword argument for this function
2017-05-12 23:25:07,556 [Thread-9:123145358184448] [django.request:132] [exception:handle_uncaught_exception] [ERROR]- Internal Server Error: /good/GoodIndexAdd/
Traceback (most recent call last):
  File "/Users/VANXV/.virtualenvs/zss322/lib/python3.6/site-packages/django/core/handlers/exception.py", line 42, in inner
    response = get_response(request)
  File "/Users/VANXV/.virtualenvs/zss322/lib/python3.6/site-packages/django/core/handlers/base.py", line 187, in _get_response
    response = self.process_exception_by_middleware(e, request)
  File "/Users/VANXV/.virtualenvs/zss322/lib/python3.6/site-packages/django/core/handlers/base.py", line 185, in _get_response
    response = wrapped_callback(request, *callback_args, **callback_kwargs)
  File "/Users/VANXV/.virtualenvs/zss322/lib/python3.6/site-packages/django/views/generic/base.py", line 68, in view
    return self.dispatch(request, *args, **kwargs)
  File "/Users/VANXV/.virtualenvs/zss322/lib/python3.6/site-packages/django/contrib/auth/mixins.py", line 56, in dispatch
    return super(LoginRequiredMixin, self).dispatch(request, *args, **kwargs)
  File "/Users/VANXV/.virtualenvs/zss322/lib/python3.6/site-packages/django/views/generic/base.py", line 88, in dispatch
    return handler(request, *args, **kwargs)
  File "/Users/VANXV/PycharmProjects/zss/goods/views.py", line 140, in post
    babyidsave = Shop.objects.create(name=test, pgoods_id=test, keyword1=test, user_id=1, shop_id=1)
  File "/Users/VANXV/.virtualenvs/zss322/lib/python3.6/site-packages/django/db/models/manager.py", line 85, in manager_method
    return getattr(self.get_queryset(), name)(*args, **kwargs)
  File "/Users/VANXV/.virtualenvs/zss322/lib/python3.6/site-packages/django/db/models/query.py", line 397, in create
    obj = self.model(**kwargs)
  File "/Users/VANXV/.virtualenvs/zss322/lib/python3.6/site-packages/django/db/models/base.py", line 555, in __init__
    raise TypeError("'%s' is an invalid keyword argument for this function" % list(kwargs)[0])
TypeError: 'name' is an invalid keyword argument for this function
2017-05-12 23:25:39,550 [Thread-9:123145480028160] [django.request:132] [exception:handle_uncaught_exception] [ERROR]- Internal Server Error: /good/GoodIndexAdd/
Traceback (most recent call last):
  File "/Users/VANXV/.virtualenvs/zss322/lib/python3.6/site-packages/django/core/handlers/exception.py", line 42, in inner
    response = get_response(request)
  File "/Users/VANXV/.virtualenvs/zss322/lib/python3.6/site-packages/django/core/handlers/base.py", line 187, in _get_response
    response = self.process_exception_by_middleware(e, request)
  File "/Users/VANXV/.virtualenvs/zss322/lib/python3.6/site-packages/django/core/handlers/base.py", line 185, in _get_response
    response = wrapped_callback(request, *callback_args, **callback_kwargs)
  File "/Users/VANXV/.virtualenvs/zss322/lib/python3.6/site-packages/django/views/generic/base.py", line 68, in view
    return self.dispatch(request, *args, **kwargs)
  File "/Users/VANXV/.virtualenvs/zss322/lib/python3.6/site-packages/django/contrib/auth/mixins.py", line 56, in dispatch
    return super(LoginRequiredMixin, self).dispatch(request, *args, **kwargs)
  File "/Users/VANXV/.virtualenvs/zss322/lib/python3.6/site-packages/django/views/generic/base.py", line 88, in dispatch
    return handler(request, *args, **kwargs)
  File "/Users/VANXV/PycharmProjects/zss/goods/views.py", line 140, in post
    babyidsave = Shop.objects.create(name=str(test), pgoods_id=test, keyword1=test, user_id=1, shop_id=1)
  File "/Users/VANXV/.virtualenvs/zss322/lib/python3.6/site-packages/django/db/models/manager.py", line 85, in manager_method
    return getattr(self.get_queryset(), name)(*args, **kwargs)
  File "/Users/VANXV/.virtualenvs/zss322/lib/python3.6/site-packages/django/db/models/query.py", line 397, in create
    obj = self.model(**kwargs)
  File "/Users/VANXV/.virtualenvs/zss322/lib/python3.6/site-packages/django/db/models/base.py", line 555, in __init__
    raise TypeError("'%s' is an invalid keyword argument for this function" % list(kwargs)[0])
TypeError: 'name' is an invalid keyword argument for this function
2017-05-13 12:36:55,159 [Thread-35:123145567023104] [django.request:152] [base:get_response] [WARNING]- Not Found: /favicon.ico
2017-05-13 14:23:58,547 [Thread-71:123145482690560] [django.request:152] [base:get_response] [WARNING]- Not Found: /reg
2017-05-13 15:19:57,543 [Thread-27:123145456447488] [django.request:152] [base:get_response] [WARNING]- Not Found: /blacklist/blacklist/
2017-05-13 15:20:13,606 [Thread-33:123145456447488] [django.request:132] [exception:handle_uncaught_exception] [ERROR]- Internal Server Error: /blacklist/
Traceback (most recent call last):
  File "/Users/VANXV/.virtualenvs/zss322/lib/python3.6/site-packages/django/db/backends/utils.py", line 64, in execute
    return self.cursor.execute(sql, params)
  File "/Users/VANXV/.virtualenvs/zss322/lib/python3.6/site-packages/django/db/backends/mysql/base.py", line 110, in execute
    return self.cursor.execute(query, args)
  File "/Users/VANXV/.virtualenvs/zss322/lib/python3.6/site-packages/pymysql/cursors.py", line 166, in execute
    result = self._query(query)
  File "/Users/VANXV/.virtualenvs/zss322/lib/python3.6/site-packages/pymysql/cursors.py", line 322, in _query
    conn.query(q)
  File "/Users/VANXV/.virtualenvs/zss322/lib/python3.6/site-packages/pymysql/connections.py", line 852, in query
    self._affected_rows = self._read_query_result(unbuffered=unbuffered)
  File "/Users/VANXV/.virtualenvs/zss322/lib/python3.6/site-packages/pymysql/connections.py", line 1053, in _read_query_result
    result.read()
  File "/Users/VANXV/.virtualenvs/zss322/lib/python3.6/site-packages/pymysql/connections.py", line 1336, in read
    first_packet = self.connection._read_packet()
  File "/Users/VANXV/.virtualenvs/zss322/lib/python3.6/site-packages/pymysql/connections.py", line 1010, in _read_packet
    packet.check_error()
  File "/Users/VANXV/.virtualenvs/zss322/lib/python3.6/site-packages/pymysql/connections.py", line 393, in check_error
    err.raise_mysql_exception(self._data)
  File "/Users/VANXV/.virtualenvs/zss322/lib/python3.6/site-packages/pymysql/err.py", line 107, in raise_mysql_exception
    raise errorclass(errno, errval)
pymysql.err.ProgrammingError: (1146, "Table 'zhess103.blacklist_blacklist' doesn't exist")

The above exception was the direct cause of the following exception:

Traceback (most recent call last):
  File "/Users/VANXV/.virtualenvs/zss322/lib/python3.6/site-packages/django/core/handlers/exception.py", line 42, in inner
    response = get_response(request)
  File "/Users/VANXV/.virtualenvs/zss322/lib/python3.6/site-packages/django/core/handlers/base.py", line 187, in _get_response
    response = self.process_exception_by_middleware(e, request)
  File "/Users/VANXV/.virtualenvs/zss322/lib/python3.6/site-packages/django/core/handlers/base.py", line 185, in _get_response
    response = wrapped_callback(request, *callback_args, **callback_kwargs)
  File "/Users/VANXV/PycharmProjects/zss/blacklist/views.py", line 9, in index
    return render(request, 'blacklist/blist.html', {'returnBlacklist':returnBlacklist})
  File "/Users/VANXV/.virtualenvs/zss322/lib/python3.6/site-packages/django/shortcuts.py", line 30, in render
    content = loader.render_to_string(template_name, context, request, using=using)
  File "/Users/VANXV/.virtualenvs/zss322/lib/python3.6/site-packages/django/template/loader.py", line 68, in render_to_string
    return template.render(context, request)
  File "/Users/VANXV/.virtualenvs/zss322/lib/python3.6/site-packages/django/template/backends/django.py", line 66, in render
    return self.template.render(context)
  File "/Users/VANXV/.virtualenvs/zss322/lib/python3.6/site-packages/django/template/base.py", line 208, in render
    return self._render(context)
  File "/Users/VANXV/.virtualenvs/zss322/lib/python3.6/site-packages/django/template/base.py", line 199, in _render
    return self.nodelist.render(context)
  File "/Users/VANXV/.virtualenvs/zss322/lib/python3.6/site-packages/django/template/base.py", line 994, in render
    bit = node.render_annotated(context)
  File "/Users/VANXV/.virtualenvs/zss322/lib/python3.6/site-packages/django/template/base.py", line 961, in render_annotated
    return self.render(context)
  File "/Users/VANXV/.virtualenvs/zss322/lib/python3.6/site-packages/django/template/defaulttags.py", line 166, in render
    len_values = len(values)
  File "/Users/VANXV/.virtualenvs/zss322/lib/python3.6/site-packages/django/db/models/query.py", line 238, in __len__
    self._fetch_all()
  File "/Users/VANXV/.virtualenvs/zss322/lib/python3.6/site-packages/django/db/models/query.py", line 1087, in _fetch_all
    self._result_cache = list(self.iterator())
  File "/Users/VANXV/.virtualenvs/zss322/lib/python3.6/site-packages/django/db/models/query.py", line 54, in __iter__
    results = compiler.execute_sql()
  File "/Users/VANXV/.virtualenvs/zss322/lib/python3.6/site-packages/django/db/models/sql/compiler.py", line 835, in execute_sql
    cursor.execute(sql, params)
  File "/Users/VANXV/.virtualenvs/zss322/lib/python3.6/site-packages/django/db/backends/utils.py", line 79, in execute
    return super(CursorDebugWrapper, self).execute(sql, params)
  File "/Users/VANXV/.virtualenvs/zss322/lib/python3.6/site-packages/django/db/backends/utils.py", line 64, in execute
    return self.cursor.execute(sql, params)
  File "/Users/VANXV/.virtualenvs/zss322/lib/python3.6/site-packages/django/db/utils.py", line 94, in __exit__
    six.reraise(dj_exc_type, dj_exc_value, traceback)
  File "/Users/VANXV/.virtualenvs/zss322/lib/python3.6/site-packages/django/utils/six.py", line 685, in reraise
    raise value.with_traceback(tb)
  File "/Users/VANXV/.virtualenvs/zss322/lib/python3.6/site-packages/django/db/backends/utils.py", line 64, in execute
    return self.cursor.execute(sql, params)
  File "/Users/VANXV/.virtualenvs/zss322/lib/python3.6/site-packages/django/db/backends/mysql/base.py", line 110, in execute
    return self.cursor.execute(query, args)
  File "/Users/VANXV/.virtualenvs/zss322/lib/python3.6/site-packages/pymysql/cursors.py", line 166, in execute
    result = self._query(query)
  File "/Users/VANXV/.virtualenvs/zss322/lib/python3.6/site-packages/pymysql/cursors.py", line 322, in _query
    conn.query(q)
  File "/Users/VANXV/.virtualenvs/zss322/lib/python3.6/site-packages/pymysql/connections.py", line 852, in query
    self._affected_rows = self._read_query_result(unbuffered=unbuffered)
  File "/Users/VANXV/.virtualenvs/zss322/lib/python3.6/site-packages/pymysql/connections.py", line 1053, in _read_query_result
    result.read()
  File "/Users/VANXV/.virtualenvs/zss322/lib/python3.6/site-packages/pymysql/connections.py", line 1336, in read
    first_packet = self.connection._read_packet()
  File "/Users/VANXV/.virtualenvs/zss322/lib/python3.6/site-packages/pymysql/connections.py", line 1010, in _read_packet
    packet.check_error()
  File "/Users/VANXV/.virtualenvs/zss322/lib/python3.6/site-packages/pymysql/connections.py", line 393, in check_error
    err.raise_mysql_exception(self._data)
  File "/Users/VANXV/.virtualenvs/zss322/lib/python3.6/site-packages/pymysql/err.py", line 107, in raise_mysql_exception
    raise errorclass(errno, errval)
django.db.utils.ProgrammingError: (1146, "Table 'zhess103.blacklist_blacklist' doesn't exist")
2017-05-13 15:21:01,872 [Thread-43:123145451192320] [django.request:152] [base:get_response] [WARNING]- Not Found: /blacklist/add
2017-05-13 15:21:43,266 [Thread-10:123145423876096] [django.request:132] [exception:handle_uncaught_exception] [ERROR]- Internal Server Error: /blacklist/add/
Traceback (most recent call last):
  File "/Users/VANXV/.virtualenvs/zss322/lib/python3.6/site-packages/django/core/handlers/exception.py", line 42, in inner
    response = get_response(request)
  File "/Users/VANXV/.virtualenvs/zss322/lib/python3.6/site-packages/django/core/handlers/base.py", line 187, in _get_response
    response = self.process_exception_by_middleware(e, request)
  File "/Users/VANXV/.virtualenvs/zss322/lib/python3.6/site-packages/django/core/handlers/base.py", line 185, in _get_response
    response = wrapped_callback(request, *callback_args, **callback_kwargs)
  File "/Users/VANXV/PycharmProjects/zss/blacklist/views.py", line 24, in add
    buyeralipay=buyeralipay, note=note)
  File "/Users/VANXV/.virtualenvs/zss322/lib/python3.6/site-packages/django/db/models/manager.py", line 85, in manager_method
    return getattr(self.get_queryset(), name)(*args, **kwargs)
  File "/Users/VANXV/.virtualenvs/zss322/lib/python3.6/site-packages/django/db/models/query.py", line 397, in create
    obj = self.model(**kwargs)
  File "/Users/VANXV/.virtualenvs/zss322/lib/python3.6/site-packages/django/db/models/base.py", line 555, in __init__
    raise TypeError("'%s' is an invalid keyword argument for this function" % list(kwargs)[0])
TypeError: 'seller' is an invalid keyword argument for this function
2017-05-13 15:22:08,509 [Thread-12:123145423876096] [django.request:132] [exception:handle_uncaught_exception] [ERROR]- Internal Server Error: /blacklist/add/
Traceback (most recent call last):
  File "/Users/VANXV/.virtualenvs/zss322/lib/python3.6/site-packages/django/core/handlers/exception.py", line 42, in inner
    response = get_response(request)
  File "/Users/VANXV/.virtualenvs/zss322/lib/python3.6/site-packages/django/core/handlers/base.py", line 187, in _get_response
    response = self.process_exception_by_middleware(e, request)
  File "/Users/VANXV/.virtualenvs/zss322/lib/python3.6/site-packages/django/core/handlers/base.py", line 185, in _get_response
    response = wrapped_callback(request, *callback_args, **callback_kwargs)
  File "/Users/VANXV/PycharmProjects/zss/blacklist/views.py", line 18, in add
    buyermobile = int(request.POST['buyermobile'])
ValueError: invalid literal for int() with base 10: '18d12'
2017-05-13 15:22:44,459 [Thread-14:123145429131264] [django.request:132] [exception:handle_uncaught_exception] [ERROR]- Internal Server Error: /blacklist/add/
Traceback (most recent call last):
  File "/Users/VANXV/.virtualenvs/zss322/lib/python3.6/site-packages/django/core/handlers/exception.py", line 42, in inner
    response = get_response(request)
  File "/Users/VANXV/.virtualenvs/zss322/lib/python3.6/site-packages/django/core/handlers/base.py", line 187, in _get_response
    response = self.process_exception_by_middleware(e, request)
  File "/Users/VANXV/.virtualenvs/zss322/lib/python3.6/site-packages/django/core/handlers/base.py", line 185, in _get_response
    response = wrapped_callback(request, *callback_args, **callback_kwargs)
  File "/Users/VANXV/PycharmProjects/zss/blacklist/views.py", line 24, in add
    buyeralipay=buyeralipay, note=note)
  File "/Users/VANXV/.virtualenvs/zss322/lib/python3.6/site-packages/django/db/models/manager.py", line 85, in manager_method
    return getattr(self.get_queryset(), name)(*args, **kwargs)
  File "/Users/VANXV/.virtualenvs/zss322/lib/python3.6/site-packages/django/db/models/query.py", line 397, in create
    obj = self.model(**kwargs)
  File "/Users/VANXV/.virtualenvs/zss322/lib/python3.6/site-packages/django/db/models/base.py", line 555, in __init__
    raise TypeError("'%s' is an invalid keyword argument for this function" % list(kwargs)[0])
TypeError: 'seller' is an invalid keyword argument for this function
