2017-05-19 12:47:24,500 [Thread-13:123145561317376] [django.request:132] [exception:handle_uncaught_exception] [ERROR]- Internal Server Error: /cryapp/GoodIndexAdd/
Traceback (most recent call last):
  File "/Users/VANXV/.virtualenvs/zss322/lib/python3.6/site-packages/django/core/handlers/exception.py", line 42, in inner
    response = get_response(request)
  File "/Users/VANXV/.virtualenvs/zss322/lib/python3.6/site-packages/django/core/handlers/base.py", line 198, in _get_response
    "returned None instead." % (callback.__module__, view_name)
ValueError: The view cryapp.views.Good_Index_Add didn't return an HttpResponse object. It returned None instead.
2017-05-19 12:48:26,668 [Thread-20:123145561317376] [django.request:132] [exception:handle_uncaught_exception] [ERROR]- Internal Server Error: /cryapp/GoodIndexAdd/
Traceback (most recent call last):
  File "/Users/VANXV/.virtualenvs/zss322/lib/python3.6/site-packages/django/core/handlers/exception.py", line 42, in inner
    response = get_response(request)
  File "/Users/VANXV/.virtualenvs/zss322/lib/python3.6/site-packages/django/core/handlers/base.py", line 198, in _get_response
    "returned None instead." % (callback.__module__, view_name)
ValueError: The view cryapp.views.Good_Index_Add didn't return an HttpResponse object. It returned None instead.
2017-05-19 15:49:52,315 [Thread-13:123145469042688] [django.request:132] [exception:handle_uncaught_exception] [ERROR]- Internal Server Error: /cryapp/GoodIndexAdd/
Traceback (most recent call last):
  File "/Users/VANXV/.virtualenvs/zss322/lib/python3.6/site-packages/django/core/handlers/exception.py", line 42, in inner
    response = get_response(request)
  File "/Users/VANXV/.virtualenvs/zss322/lib/python3.6/site-packages/django/core/handlers/base.py", line 187, in _get_response
    response = self.process_exception_by_middleware(e, request)
  File "/Users/VANXV/.virtualenvs/zss322/lib/python3.6/site-packages/django/core/handlers/base.py", line 185, in _get_response
    response = wrapped_callback(request, *callback_args, **callback_kwargs)
  File "/Users/VANXV/.virtualenvs/zss322/lib/python3.6/site-packages/django/views/generic/base.py", line 68, in view
    return self.dispatch(request, *args, **kwargs)
  File "/Users/VANXV/.virtualenvs/zss322/lib/python3.6/site-packages/django/contrib/auth/mixins.py", line 56, in dispatch
    return super(LoginRequiredMixin, self).dispatch(request, *args, **kwargs)
  File "/Users/VANXV/.virtualenvs/zss322/lib/python3.6/site-packages/django/views/generic/base.py", line 88, in dispatch
    return handler(request, *args, **kwargs)
  File "/Users/VANXV/PycharmProjects/zss/cryapp/views.py", line 77, in post
    tempGoodsTrue = Goods.objects.filter(pgoods_id=id, platform=platform, shopname__id__contains=shopname)
  File "/Users/VANXV/.virtualenvs/zss322/lib/python3.6/site-packages/django/db/models/manager.py", line 85, in manager_method
    return getattr(self.get_queryset(), name)(*args, **kwargs)
  File "/Users/VANXV/.virtualenvs/zss322/lib/python3.6/site-packages/django/db/models/query.py", line 796, in filter
    return self._filter_or_exclude(False, *args, **kwargs)
  File "/Users/VANXV/.virtualenvs/zss322/lib/python3.6/site-packages/django/db/models/query.py", line 814, in _filter_or_exclude
    clone.query.add_q(Q(*args, **kwargs))
  File "/Users/VANXV/.virtualenvs/zss322/lib/python3.6/site-packages/django/db/models/sql/query.py", line 1227, in add_q
    clause, _ = self._add_q(q_object, self.used_aliases)
  File "/Users/VANXV/.virtualenvs/zss322/lib/python3.6/site-packages/django/db/models/sql/query.py", line 1253, in _add_q
    allow_joins=allow_joins, split_subq=split_subq,
  File "/Users/VANXV/.virtualenvs/zss322/lib/python3.6/site-packages/django/db/models/sql/query.py", line 1133, in build_filter
    lookups, parts, reffed_expression = self.solve_lookup_type(arg)
  File "/Users/VANXV/.virtualenvs/zss322/lib/python3.6/site-packages/django/db/models/sql/query.py", line 1019, in solve_lookup_type
    _, field, _, lookup_parts = self.names_to_path(lookup_splitted, self.get_meta())
  File "/Users/VANXV/.virtualenvs/zss322/lib/python3.6/site-packages/django/db/models/sql/query.py", line 1327, in names_to_path
    "Choices are: %s" % (name, ", ".join(available)))
django.core.exceptions.FieldError: Cannot resolve keyword 'shopname' into field. Choices are: add_time, cryorder, id, image1, image2, image3, keywor5, keyword1, keyword2, keyword3, keyword4, name, pgoods_id, platform, price1, price2, price3, price4, price5, remark1, remark2, remark3, remark4, remark5, sendaddress, shop, shop_id, user, user_id
2017-05-19 15:50:52,699 [Thread-20:123145469042688] [django.request:132] [exception:handle_uncaught_exception] [ERROR]- Internal Server Error: /cryapp/GoodIndexAdd/
Traceback (most recent call last):
  File "/Users/VANXV/.virtualenvs/zss322/lib/python3.6/site-packages/django/core/handlers/exception.py", line 42, in inner
    response = get_response(request)
  File "/Users/VANXV/.virtualenvs/zss322/lib/python3.6/site-packages/django/core/handlers/base.py", line 187, in _get_response
    response = self.process_exception_by_middleware(e, request)
  File "/Users/VANXV/.virtualenvs/zss322/lib/python3.6/site-packages/django/core/handlers/base.py", line 185, in _get_response
    response = wrapped_callback(request, *callback_args, **callback_kwargs)
  File "/Users/VANXV/.virtualenvs/zss322/lib/python3.6/site-packages/django/views/generic/base.py", line 68, in view
    return self.dispatch(request, *args, **kwargs)
  File "/Users/VANXV/.virtualenvs/zss322/lib/python3.6/site-packages/django/contrib/auth/mixins.py", line 56, in dispatch
    return super(LoginRequiredMixin, self).dispatch(request, *args, **kwargs)
  File "/Users/VANXV/.virtualenvs/zss322/lib/python3.6/site-packages/django/views/generic/base.py", line 88, in dispatch
    return handler(request, *args, **kwargs)
  File "/Users/VANXV/PycharmProjects/zss/cryapp/views.py", line 77, in post
    tempGoodsTrue = Goods.objects.filter(pgoods_id=id, platform=platform, shopname__id__contains=shopname)
  File "/Users/VANXV/.virtualenvs/zss322/lib/python3.6/site-packages/django/db/models/manager.py", line 85, in manager_method
    return getattr(self.get_queryset(), name)(*args, **kwargs)
  File "/Users/VANXV/.virtualenvs/zss322/lib/python3.6/site-packages/django/db/models/query.py", line 796, in filter
    return self._filter_or_exclude(False, *args, **kwargs)
  File "/Users/VANXV/.virtualenvs/zss322/lib/python3.6/site-packages/django/db/models/query.py", line 814, in _filter_or_exclude
    clone.query.add_q(Q(*args, **kwargs))
  File "/Users/VANXV/.virtualenvs/zss322/lib/python3.6/site-packages/django/db/models/sql/query.py", line 1227, in add_q
    clause, _ = self._add_q(q_object, self.used_aliases)
  File "/Users/VANXV/.virtualenvs/zss322/lib/python3.6/site-packages/django/db/models/sql/query.py", line 1253, in _add_q
    allow_joins=allow_joins, split_subq=split_subq,
  File "/Users/VANXV/.virtualenvs/zss322/lib/python3.6/site-packages/django/db/models/sql/query.py", line 1133, in build_filter
    lookups, parts, reffed_expression = self.solve_lookup_type(arg)
  File "/Users/VANXV/.virtualenvs/zss322/lib/python3.6/site-packages/django/db/models/sql/query.py", line 1019, in solve_lookup_type
    _, field, _, lookup_parts = self.names_to_path(lookup_splitted, self.get_meta())
  File "/Users/VANXV/.virtualenvs/zss322/lib/python3.6/site-packages/django/db/models/sql/query.py", line 1327, in names_to_path
    "Choices are: %s" % (name, ", ".join(available)))
django.core.exceptions.FieldError: Cannot resolve keyword 'shopname' into field. Choices are: add_time, cryorder, id, image1, image2, image3, keywor5, keyword1, keyword2, keyword3, keyword4, name, pgoods_id, platform, price1, price2, price3, price4, price5, remark1, remark2, remark3, remark4, remark5, sendaddress, shop, shop_id, user, user_id
2017-05-19 15:51:53,958 [Thread-27:123145469042688] [django.request:132] [exception:handle_uncaught_exception] [ERROR]- Internal Server Error: /cryapp/GoodIndexAdd/
Traceback (most recent call last):
  File "/Users/VANXV/.virtualenvs/zss322/lib/python3.6/site-packages/django/core/handlers/exception.py", line 42, in inner
    response = get_response(request)
  File "/Users/VANXV/.virtualenvs/zss322/lib/python3.6/site-packages/django/core/handlers/base.py", line 187, in _get_response
    response = self.process_exception_by_middleware(e, request)
  File "/Users/VANXV/.virtualenvs/zss322/lib/python3.6/site-packages/django/core/handlers/base.py", line 185, in _get_response
    response = wrapped_callback(request, *callback_args, **callback_kwargs)
  File "/Users/VANXV/.virtualenvs/zss322/lib/python3.6/site-packages/django/views/generic/base.py", line 68, in view
    return self.dispatch(request, *args, **kwargs)
  File "/Users/VANXV/.virtualenvs/zss322/lib/python3.6/site-packages/django/contrib/auth/mixins.py", line 56, in dispatch
    return super(LoginRequiredMixin, self).dispatch(request, *args, **kwargs)
  File "/Users/VANXV/.virtualenvs/zss322/lib/python3.6/site-packages/django/views/generic/base.py", line 88, in dispatch
    return handler(request, *args, **kwargs)
  File "/Users/VANXV/PycharmProjects/zss/cryapp/views.py", line 77, in post
    tempGoodsTrue = Goods.objects.filter(pgoods_id=id, platform=platform, shopname__id__contains=shopname)
  File "/Users/VANXV/.virtualenvs/zss322/lib/python3.6/site-packages/django/db/models/manager.py", line 85, in manager_method
    return getattr(self.get_queryset(), name)(*args, **kwargs)
  File "/Users/VANXV/.virtualenvs/zss322/lib/python3.6/site-packages/django/db/models/query.py", line 796, in filter
    return self._filter_or_exclude(False, *args, **kwargs)
  File "/Users/VANXV/.virtualenvs/zss322/lib/python3.6/site-packages/django/db/models/query.py", line 814, in _filter_or_exclude
    clone.query.add_q(Q(*args, **kwargs))
  File "/Users/VANXV/.virtualenvs/zss322/lib/python3.6/site-packages/django/db/models/sql/query.py", line 1227, in add_q
    clause, _ = self._add_q(q_object, self.used_aliases)
  File "/Users/VANXV/.virtualenvs/zss322/lib/python3.6/site-packages/django/db/models/sql/query.py", line 1253, in _add_q
    allow_joins=allow_joins, split_subq=split_subq,
  File "/Users/VANXV/.virtualenvs/zss322/lib/python3.6/site-packages/django/db/models/sql/query.py", line 1133, in build_filter
    lookups, parts, reffed_expression = self.solve_lookup_type(arg)
  File "/Users/VANXV/.virtualenvs/zss322/lib/python3.6/site-packages/django/db/models/sql/query.py", line 1019, in solve_lookup_type
    _, field, _, lookup_parts = self.names_to_path(lookup_splitted, self.get_meta())
  File "/Users/VANXV/.virtualenvs/zss322/lib/python3.6/site-packages/django/db/models/sql/query.py", line 1327, in names_to_path
    "Choices are: %s" % (name, ", ".join(available)))
django.core.exceptions.FieldError: Cannot resolve keyword 'shopname' into field. Choices are: add_time, cryorder, id, image1, image2, image3, keywor5, keyword1, keyword2, keyword3, keyword4, name, pgoods_id, platform, price1, price2, price3, price4, price5, remark1, remark2, remark3, remark4, remark5, sendaddress, shop, shop_id, user, user_id
2017-05-19 16:14:19,310 [Thread-13:123145581522944] [django.request:132] [exception:handle_uncaught_exception] [ERROR]- Internal Server Error: /cryapp/GoodIndexAdd/
Traceback (most recent call last):
  File "/Users/VANXV/.virtualenvs/zss322/lib/python3.6/site-packages/django/core/handlers/exception.py", line 42, in inner
    response = get_response(request)
  File "/Users/VANXV/.virtualenvs/zss322/lib/python3.6/site-packages/django/core/handlers/base.py", line 187, in _get_response
    response = self.process_exception_by_middleware(e, request)
  File "/Users/VANXV/.virtualenvs/zss322/lib/python3.6/site-packages/django/core/handlers/base.py", line 185, in _get_response
    response = wrapped_callback(request, *callback_args, **callback_kwargs)
  File "/Users/VANXV/.virtualenvs/zss322/lib/python3.6/site-packages/django/views/generic/base.py", line 68, in view
    return self.dispatch(request, *args, **kwargs)
  File "/Users/VANXV/.virtualenvs/zss322/lib/python3.6/site-packages/django/contrib/auth/mixins.py", line 56, in dispatch
    return super(LoginRequiredMixin, self).dispatch(request, *args, **kwargs)
  File "/Users/VANXV/.virtualenvs/zss322/lib/python3.6/site-packages/django/views/generic/base.py", line 88, in dispatch
    return handler(request, *args, **kwargs)
  File "/Users/VANXV/PycharmProjects/zss/cryapp/views.py", line 92, in post
    savegroup.saveshop(userid, shopname, shopusername, platform)
TypeError: saveshop() missing 1 required positional argument: 'platform'
2017-05-19 16:15:31,787 [Thread-9:123145437175808] [django.request:132] [exception:handle_uncaught_exception] [ERROR]- Internal Server Error: /cryapp/GoodIndexAdd/
Traceback (most recent call last):
  File "/Users/VANXV/.virtualenvs/zss322/lib/python3.6/site-packages/django/core/handlers/exception.py", line 42, in inner
    response = get_response(request)
  File "/Users/VANXV/.virtualenvs/zss322/lib/python3.6/site-packages/django/core/handlers/base.py", line 187, in _get_response
    response = self.process_exception_by_middleware(e, request)
  File "/Users/VANXV/.virtualenvs/zss322/lib/python3.6/site-packages/django/core/handlers/base.py", line 185, in _get_response
    response = wrapped_callback(request, *callback_args, **callback_kwargs)
  File "/Users/VANXV/.virtualenvs/zss322/lib/python3.6/site-packages/django/views/generic/base.py", line 68, in view
    return self.dispatch(request, *args, **kwargs)
  File "/Users/VANXV/.virtualenvs/zss322/lib/python3.6/site-packages/django/contrib/auth/mixins.py", line 56, in dispatch
    return super(LoginRequiredMixin, self).dispatch(request, *args, **kwargs)
  File "/Users/VANXV/.virtualenvs/zss322/lib/python3.6/site-packages/django/views/generic/base.py", line 88, in dispatch
    return handler(request, *args, **kwargs)
  File "/Users/VANXV/PycharmProjects/zss/cryapp/views.py", line 92, in post
    savegroup.saveshop(self, userid, shopname, shopusername, platform)
  File "/Users/VANXV/PycharmProjects/zss/cryapp/views.py", line 53, in saveshop
    saveshop = Shop.objects.create(user=user, shopname=shopname,shopkeepername=shopkeepername,platform=platform)
  File "/Users/VANXV/.virtualenvs/zss322/lib/python3.6/site-packages/django/db/models/manager.py", line 85, in manager_method
    return getattr(self.get_queryset(), name)(*args, **kwargs)
  File "/Users/VANXV/.virtualenvs/zss322/lib/python3.6/site-packages/django/db/models/query.py", line 397, in create
    obj = self.model(**kwargs)
  File "/Users/VANXV/.virtualenvs/zss322/lib/python3.6/site-packages/django/db/models/base.py", line 537, in __init__
    setattr(self, field.name, rel_obj)
  File "/Users/VANXV/.virtualenvs/zss322/lib/python3.6/site-packages/django/db/models/fields/related_descriptors.py", line 211, in __set__
    self.field.remote_field.model._meta.object_name,
ValueError: Cannot assign "1": "Shop.user" must be a "AuthUser" instance.
2017-05-19 16:17:50,659 [Thread-13:123145399422976] [django.request:132] [exception:handle_uncaught_exception] [ERROR]- Internal Server Error: /cryapp/GoodIndexAdd/
Traceback (most recent call last):
  File "/Users/VANXV/.virtualenvs/zss322/lib/python3.6/site-packages/django/core/handlers/exception.py", line 42, in inner
    response = get_response(request)
  File "/Users/VANXV/.virtualenvs/zss322/lib/python3.6/site-packages/django/core/handlers/base.py", line 187, in _get_response
    response = self.process_exception_by_middleware(e, request)
  File "/Users/VANXV/.virtualenvs/zss322/lib/python3.6/site-packages/django/core/handlers/base.py", line 185, in _get_response
    response = wrapped_callback(request, *callback_args, **callback_kwargs)
  File "/Users/VANXV/.virtualenvs/zss322/lib/python3.6/site-packages/django/views/generic/base.py", line 68, in view
    return self.dispatch(request, *args, **kwargs)
  File "/Users/VANXV/.virtualenvs/zss322/lib/python3.6/site-packages/django/contrib/auth/mixins.py", line 56, in dispatch
    return super(LoginRequiredMixin, self).dispatch(request, *args, **kwargs)
  File "/Users/VANXV/.virtualenvs/zss322/lib/python3.6/site-packages/django/views/generic/base.py", line 88, in dispatch
    return handler(request, *args, **kwargs)
  File "/Users/VANXV/PycharmProjects/zss/cryapp/views.py", line 92, in post
    savegroup.saveshop(self, userid, shopname, shopusername, platform)
  File "/Users/VANXV/PycharmProjects/zss/cryapp/views.py", line 53, in saveshop
    saveshop = Shop.objects.create(user=user, shopname=shopname,shopkeepername=shopkeepername,platform=platform)
  File "/Users/VANXV/.virtualenvs/zss322/lib/python3.6/site-packages/django/db/models/manager.py", line 85, in manager_method
    return getattr(self.get_queryset(), name)(*args, **kwargs)
  File "/Users/VANXV/.virtualenvs/zss322/lib/python3.6/site-packages/django/db/models/query.py", line 397, in create
    obj = self.model(**kwargs)
  File "/Users/VANXV/.virtualenvs/zss322/lib/python3.6/site-packages/django/db/models/base.py", line 537, in __init__
    setattr(self, field.name, rel_obj)
  File "/Users/VANXV/.virtualenvs/zss322/lib/python3.6/site-packages/django/db/models/fields/related_descriptors.py", line 211, in __set__
    self.field.remote_field.model._meta.object_name,
ValueError: Cannot assign "1": "Shop.user" must be a "AuthUser" instance.
2017-05-19 16:19:28,370 [Thread-16:123145411543040] [django.request:132] [exception:handle_uncaught_exception] [ERROR]- Internal Server Error: /cryapp/GoodIndexAdd/
Traceback (most recent call last):
  File "/Users/VANXV/.virtualenvs/zss322/lib/python3.6/site-packages/django/core/handlers/exception.py", line 42, in inner
    response = get_response(request)
  File "/Users/VANXV/.virtualenvs/zss322/lib/python3.6/site-packages/django/core/handlers/base.py", line 187, in _get_response
    response = self.process_exception_by_middleware(e, request)
  File "/Users/VANXV/.virtualenvs/zss322/lib/python3.6/site-packages/django/core/handlers/base.py", line 185, in _get_response
    response = wrapped_callback(request, *callback_args, **callback_kwargs)
  File "/Users/VANXV/.virtualenvs/zss322/lib/python3.6/site-packages/django/views/generic/base.py", line 68, in view
    return self.dispatch(request, *args, **kwargs)
  File "/Users/VANXV/.virtualenvs/zss322/lib/python3.6/site-packages/django/contrib/auth/mixins.py", line 56, in dispatch
    return super(LoginRequiredMixin, self).dispatch(request, *args, **kwargs)
  File "/Users/VANXV/.virtualenvs/zss322/lib/python3.6/site-packages/django/views/generic/base.py", line 88, in dispatch
    return handler(request, *args, **kwargs)
  File "/Users/VANXV/PycharmProjects/zss/cryapp/views.py", line 92, in post
    savegroup.saveshop(self, userid, shopname, shopusername, platform)
  File "/Users/VANXV/PycharmProjects/zss/cryapp/views.py", line 53, in saveshop
    saveshop = Shop.objects.create(user=user, shopname=shopname,shopkeepername=shopkeepername,platform=platform)
  File "/Users/VANXV/.virtualenvs/zss322/lib/python3.6/site-packages/django/db/models/manager.py", line 85, in manager_method
    return getattr(self.get_queryset(), name)(*args, **kwargs)
  File "/Users/VANXV/.virtualenvs/zss322/lib/python3.6/site-packages/django/db/models/query.py", line 397, in create
    obj = self.model(**kwargs)
  File "/Users/VANXV/.virtualenvs/zss322/lib/python3.6/site-packages/django/db/models/base.py", line 537, in __init__
    setattr(self, field.name, rel_obj)
  File "/Users/VANXV/.virtualenvs/zss322/lib/python3.6/site-packages/django/db/models/fields/related_descriptors.py", line 211, in __set__
    self.field.remote_field.model._meta.object_name,
ValueError: Cannot assign "1": "Shop.user" must be a "AuthUser" instance.
2017-05-19 16:21:39,617 [Thread-13:123145512697856] [django.request:132] [exception:handle_uncaught_exception] [ERROR]- Internal Server Error: /cryapp/GoodIndexAdd/
Traceback (most recent call last):
  File "/Users/VANXV/.virtualenvs/zss322/lib/python3.6/site-packages/django/core/handlers/exception.py", line 42, in inner
    response = get_response(request)
  File "/Users/VANXV/.virtualenvs/zss322/lib/python3.6/site-packages/django/core/handlers/base.py", line 187, in _get_response
    response = self.process_exception_by_middleware(e, request)
  File "/Users/VANXV/.virtualenvs/zss322/lib/python3.6/site-packages/django/core/handlers/base.py", line 185, in _get_response
    response = wrapped_callback(request, *callback_args, **callback_kwargs)
  File "/Users/VANXV/.virtualenvs/zss322/lib/python3.6/site-packages/django/views/generic/base.py", line 68, in view
    return self.dispatch(request, *args, **kwargs)
  File "/Users/VANXV/.virtualenvs/zss322/lib/python3.6/site-packages/django/contrib/auth/mixins.py", line 56, in dispatch
    return super(LoginRequiredMixin, self).dispatch(request, *args, **kwargs)
  File "/Users/VANXV/.virtualenvs/zss322/lib/python3.6/site-packages/django/views/generic/base.py", line 88, in dispatch
    return handler(request, *args, **kwargs)
  File "/Users/VANXV/PycharmProjects/zss/cryapp/views.py", line 92, in post
    savegroup.saveshop(self, request.user.id, shopname, shopusername, platform)
  File "/Users/VANXV/PycharmProjects/zss/cryapp/views.py", line 53, in saveshop
    saveshop = Shop.objects.create(user=user, shopname=shopname,shopkeepername=shopkeepername,platform=platform)
  File "/Users/VANXV/.virtualenvs/zss322/lib/python3.6/site-packages/django/db/models/manager.py", line 85, in manager_method
    return getattr(self.get_queryset(), name)(*args, **kwargs)
  File "/Users/VANXV/.virtualenvs/zss322/lib/python3.6/site-packages/django/db/models/query.py", line 397, in create
    obj = self.model(**kwargs)
  File "/Users/VANXV/.virtualenvs/zss322/lib/python3.6/site-packages/django/db/models/base.py", line 537, in __init__
    setattr(self, field.name, rel_obj)
  File "/Users/VANXV/.virtualenvs/zss322/lib/python3.6/site-packages/django/db/models/fields/related_descriptors.py", line 211, in __set__
    self.field.remote_field.model._meta.object_name,
ValueError: Cannot assign "1": "Shop.user" must be a "AuthUser" instance.
2017-05-19 16:23:20,676 [Thread-13:123145348861952] [django.request:132] [exception:handle_uncaught_exception] [ERROR]- Internal Server Error: /cryapp/GoodIndexAdd/
Traceback (most recent call last):
  File "/Users/VANXV/.virtualenvs/zss322/lib/python3.6/site-packages/django/core/handlers/exception.py", line 42, in inner
    response = get_response(request)
  File "/Users/VANXV/.virtualenvs/zss322/lib/python3.6/site-packages/django/core/handlers/base.py", line 187, in _get_response
    response = self.process_exception_by_middleware(e, request)
  File "/Users/VANXV/.virtualenvs/zss322/lib/python3.6/site-packages/django/core/handlers/base.py", line 185, in _get_response
    response = wrapped_callback(request, *callback_args, **callback_kwargs)
  File "/Users/VANXV/.virtualenvs/zss322/lib/python3.6/site-packages/django/views/generic/base.py", line 68, in view
    return self.dispatch(request, *args, **kwargs)
  File "/Users/VANXV/.virtualenvs/zss322/lib/python3.6/site-packages/django/contrib/auth/mixins.py", line 56, in dispatch
    return super(LoginRequiredMixin, self).dispatch(request, *args, **kwargs)
  File "/Users/VANXV/.virtualenvs/zss322/lib/python3.6/site-packages/django/views/generic/base.py", line 88, in dispatch
    return handler(request, *args, **kwargs)
  File "/Users/VANXV/PycharmProjects/zss/cryapp/views.py", line 93, in post
    platform=platform)
  File "/Users/VANXV/.virtualenvs/zss322/lib/python3.6/site-packages/django/db/models/manager.py", line 85, in manager_method
    return getattr(self.get_queryset(), name)(*args, **kwargs)
  File "/Users/VANXV/.virtualenvs/zss322/lib/python3.6/site-packages/django/db/models/query.py", line 397, in create
    obj = self.model(**kwargs)
  File "/Users/VANXV/.virtualenvs/zss322/lib/python3.6/site-packages/django/db/models/base.py", line 537, in __init__
    setattr(self, field.name, rel_obj)
  File "/Users/VANXV/.virtualenvs/zss322/lib/python3.6/site-packages/django/db/models/fields/related_descriptors.py", line 211, in __set__
    self.field.remote_field.model._meta.object_name,
ValueError: Cannot assign "1": "Shop.user" must be a "AuthUser" instance.
2017-05-19 16:24:32,161 [Thread-9:123145443655680] [django.request:132] [exception:handle_uncaught_exception] [ERROR]- Internal Server Error: /cryapp/GoodIndexAdd/
Traceback (most recent call last):
  File "/Users/VANXV/.virtualenvs/zss322/lib/python3.6/site-packages/django/db/backends/utils.py", line 64, in execute
    return self.cursor.execute(sql, params)
  File "/Users/VANXV/.virtualenvs/zss322/lib/python3.6/site-packages/django/db/backends/mysql/base.py", line 110, in execute
    return self.cursor.execute(query, args)
  File "/Users/VANXV/.virtualenvs/zss322/lib/python3.6/site-packages/pymysql/cursors.py", line 166, in execute
    result = self._query(query)
  File "/Users/VANXV/.virtualenvs/zss322/lib/python3.6/site-packages/pymysql/cursors.py", line 322, in _query
    conn.query(q)
  File "/Users/VANXV/.virtualenvs/zss322/lib/python3.6/site-packages/pymysql/connections.py", line 852, in query
    self._affected_rows = self._read_query_result(unbuffered=unbuffered)
  File "/Users/VANXV/.virtualenvs/zss322/lib/python3.6/site-packages/pymysql/connections.py", line 1053, in _read_query_result
    result.read()
  File "/Users/VANXV/.virtualenvs/zss322/lib/python3.6/site-packages/pymysql/connections.py", line 1336, in read
    first_packet = self.connection._read_packet()
  File "/Users/VANXV/.virtualenvs/zss322/lib/python3.6/site-packages/pymysql/connections.py", line 1010, in _read_packet
    packet.check_error()
  File "/Users/VANXV/.virtualenvs/zss322/lib/python3.6/site-packages/pymysql/connections.py", line 393, in check_error
    err.raise_mysql_exception(self._data)
  File "/Users/VANXV/.virtualenvs/zss322/lib/python3.6/site-packages/pymysql/err.py", line 107, in raise_mysql_exception
    raise errorclass(errno, errval)
pymysql.err.DataError: (1406, "Data too long for column 'name' at row 1")

The above exception was the direct cause of the following exception:

Traceback (most recent call last):
  File "/Users/VANXV/.virtualenvs/zss322/lib/python3.6/site-packages/django/core/handlers/exception.py", line 42, in inner
    response = get_response(request)
  File "/Users/VANXV/.virtualenvs/zss322/lib/python3.6/site-packages/django/core/handlers/base.py", line 187, in _get_response
    response = self.process_exception_by_middleware(e, request)
  File "/Users/VANXV/.virtualenvs/zss322/lib/python3.6/site-packages/django/core/handlers/base.py", line 185, in _get_response
    response = wrapped_callback(request, *callback_args, **callback_kwargs)
  File "/Users/VANXV/.virtualenvs/zss322/lib/python3.6/site-packages/django/views/generic/base.py", line 68, in view
    return self.dispatch(request, *args, **kwargs)
  File "/Users/VANXV/.virtualenvs/zss322/lib/python3.6/site-packages/django/contrib/auth/mixins.py", line 56, in dispatch
    return super(LoginRequiredMixin, self).dispatch(request, *args, **kwargs)
  File "/Users/VANXV/.virtualenvs/zss322/lib/python3.6/site-packages/django/views/generic/base.py", line 88, in dispatch
    return handler(request, *args, **kwargs)
  File "/Users/VANXV/PycharmProjects/zss/cryapp/views.py", line 95, in post
    babyidsave = Goods.objects.create(name=str(txtIndexAddUrl), pgoods_id=id, keyword1=keywords, user_id=1, shop_id=1)
  File "/Users/VANXV/.virtualenvs/zss322/lib/python3.6/site-packages/django/db/models/manager.py", line 85, in manager_method
    return getattr(self.get_queryset(), name)(*args, **kwargs)
  File "/Users/VANXV/.virtualenvs/zss322/lib/python3.6/site-packages/django/db/models/query.py", line 399, in create
    obj.save(force_insert=True, using=self.db)
  File "/Users/VANXV/.virtualenvs/zss322/lib/python3.6/site-packages/django/db/models/base.py", line 796, in save
    force_update=force_update, update_fields=update_fields)
  File "/Users/VANXV/.virtualenvs/zss322/lib/python3.6/site-packages/django/db/models/base.py", line 824, in save_base
    updated = self._save_table(raw, cls, force_insert, force_update, using, update_fields)
  File "/Users/VANXV/.virtualenvs/zss322/lib/python3.6/site-packages/django/db/models/base.py", line 908, in _save_table
    result = self._do_insert(cls._base_manager, using, fields, update_pk, raw)
  File "/Users/VANXV/.virtualenvs/zss322/lib/python3.6/site-packages/django/db/models/base.py", line 947, in _do_insert
    using=using, raw=raw)
  File "/Users/VANXV/.virtualenvs/zss322/lib/python3.6/site-packages/django/db/models/manager.py", line 85, in manager_method
    return getattr(self.get_queryset(), name)(*args, **kwargs)
  File "/Users/VANXV/.virtualenvs/zss322/lib/python3.6/site-packages/django/db/models/query.py", line 1045, in _insert
    return query.get_compiler(using=using).execute_sql(return_id)
  File "/Users/VANXV/.virtualenvs/zss322/lib/python3.6/site-packages/django/db/models/sql/compiler.py", line 1054, in execute_sql
    cursor.execute(sql, params)
  File "/Users/VANXV/.virtualenvs/zss322/lib/python3.6/site-packages/django/db/backends/utils.py", line 79, in execute
    return super(CursorDebugWrapper, self).execute(sql, params)
  File "/Users/VANXV/.virtualenvs/zss322/lib/python3.6/site-packages/django/db/backends/utils.py", line 64, in execute
    return self.cursor.execute(sql, params)
  File "/Users/VANXV/.virtualenvs/zss322/lib/python3.6/site-packages/django/db/utils.py", line 94, in __exit__
    six.reraise(dj_exc_type, dj_exc_value, traceback)
  File "/Users/VANXV/.virtualenvs/zss322/lib/python3.6/site-packages/django/utils/six.py", line 685, in reraise
    raise value.with_traceback(tb)
  File "/Users/VANXV/.virtualenvs/zss322/lib/python3.6/site-packages/django/db/backends/utils.py", line 64, in execute
    return self.cursor.execute(sql, params)
  File "/Users/VANXV/.virtualenvs/zss322/lib/python3.6/site-packages/django/db/backends/mysql/base.py", line 110, in execute
    return self.cursor.execute(query, args)
  File "/Users/VANXV/.virtualenvs/zss322/lib/python3.6/site-packages/pymysql/cursors.py", line 166, in execute
    result = self._query(query)
  File "/Users/VANXV/.virtualenvs/zss322/lib/python3.6/site-packages/pymysql/cursors.py", line 322, in _query
    conn.query(q)
  File "/Users/VANXV/.virtualenvs/zss322/lib/python3.6/site-packages/pymysql/connections.py", line 852, in query
    self._affected_rows = self._read_query_result(unbuffered=unbuffered)
  File "/Users/VANXV/.virtualenvs/zss322/lib/python3.6/site-packages/pymysql/connections.py", line 1053, in _read_query_result
    result.read()
  File "/Users/VANXV/.virtualenvs/zss322/lib/python3.6/site-packages/pymysql/connections.py", line 1336, in read
    first_packet = self.connection._read_packet()
  File "/Users/VANXV/.virtualenvs/zss322/lib/python3.6/site-packages/pymysql/connections.py", line 1010, in _read_packet
    packet.check_error()
  File "/Users/VANXV/.virtualenvs/zss322/lib/python3.6/site-packages/pymysql/connections.py", line 393, in check_error
    err.raise_mysql_exception(self._data)
  File "/Users/VANXV/.virtualenvs/zss322/lib/python3.6/site-packages/pymysql/err.py", line 107, in raise_mysql_exception
    raise errorclass(errno, errval)
django.db.utils.DataError: (1406, "Data too long for column 'name' at row 1")
2017-05-19 16:30:56,939 [Thread-10:123145520984064] [django.request:132] [exception:handle_uncaught_exception] [ERROR]- Internal Server Error: /cryapp/GoodIndexAdd/
Traceback (most recent call last):
  File "/Users/VANXV/.virtualenvs/zss322/lib/python3.6/site-packages/django/core/handlers/exception.py", line 42, in inner
    response = get_response(request)
  File "/Users/VANXV/.virtualenvs/zss322/lib/python3.6/site-packages/django/core/handlers/base.py", line 187, in _get_response
    response = self.process_exception_by_middleware(e, request)
  File "/Users/VANXV/.virtualenvs/zss322/lib/python3.6/site-packages/django/core/handlers/base.py", line 185, in _get_response
    response = wrapped_callback(request, *callback_args, **callback_kwargs)
  File "/Users/VANXV/.virtualenvs/zss322/lib/python3.6/site-packages/django/views/generic/base.py", line 68, in view
    return self.dispatch(request, *args, **kwargs)
  File "/Users/VANXV/.virtualenvs/zss322/lib/python3.6/site-packages/django/contrib/auth/mixins.py", line 56, in dispatch
    return super(LoginRequiredMixin, self).dispatch(request, *args, **kwargs)
  File "/Users/VANXV/.virtualenvs/zss322/lib/python3.6/site-packages/django/views/generic/base.py", line 88, in dispatch
    return handler(request, *args, **kwargs)
  File "/Users/VANXV/PycharmProjects/zss/cryapp/views.py", line 93, in post
    platform=platform)
  File "/Users/VANXV/.virtualenvs/zss322/lib/python3.6/site-packages/django/db/models/manager.py", line 85, in manager_method
    return getattr(self.get_queryset(), name)(*args, **kwargs)
  File "/Users/VANXV/.virtualenvs/zss322/lib/python3.6/site-packages/django/db/models/query.py", line 397, in create
    obj = self.model(**kwargs)
  File "/Users/VANXV/.virtualenvs/zss322/lib/python3.6/site-packages/django/db/models/base.py", line 555, in __init__
    raise TypeError("'%s' is an invalid keyword argument for this function" % list(kwargs)[0])
TypeError: 'userid' is an invalid keyword argument for this function
2017-05-19 16:32:15,603 [Thread-11:123145401339904] [django.request:132] [exception:handle_uncaught_exception] [ERROR]- Internal Server Error: /cryapp/GoodIndexAdd/
Traceback (most recent call last):
  File "/Users/VANXV/.virtualenvs/zss322/lib/python3.6/site-packages/django/core/handlers/exception.py", line 42, in inner
    response = get_response(request)
  File "/Users/VANXV/.virtualenvs/zss322/lib/python3.6/site-packages/django/core/handlers/base.py", line 187, in _get_response
    response = self.process_exception_by_middleware(e, request)
  File "/Users/VANXV/.virtualenvs/zss322/lib/python3.6/site-packages/django/core/handlers/base.py", line 185, in _get_response
    response = wrapped_callback(request, *callback_args, **callback_kwargs)
  File "/Users/VANXV/.virtualenvs/zss322/lib/python3.6/site-packages/django/views/generic/base.py", line 68, in view
    return self.dispatch(request, *args, **kwargs)
  File "/Users/VANXV/.virtualenvs/zss322/lib/python3.6/site-packages/django/contrib/auth/mixins.py", line 56, in dispatch
    return super(LoginRequiredMixin, self).dispatch(request, *args, **kwargs)
  File "/Users/VANXV/.virtualenvs/zss322/lib/python3.6/site-packages/django/views/generic/base.py", line 88, in dispatch
    return handler(request, *args, **kwargs)
  File "/Users/VANXV/PycharmProjects/zss/cryapp/views.py", line 93, in post
    platform=platform)
  File "/Users/VANXV/.virtualenvs/zss322/lib/python3.6/site-packages/django/db/models/manager.py", line 85, in manager_method
    return getattr(self.get_queryset(), name)(*args, **kwargs)
  File "/Users/VANXV/.virtualenvs/zss322/lib/python3.6/site-packages/django/db/models/query.py", line 397, in create
    obj = self.model(**kwargs)
  File "/Users/VANXV/.virtualenvs/zss322/lib/python3.6/site-packages/django/db/models/base.py", line 537, in __init__
    setattr(self, field.name, rel_obj)
  File "/Users/VANXV/.virtualenvs/zss322/lib/python3.6/site-packages/django/db/models/fields/related_descriptors.py", line 211, in __set__
    self.field.remote_field.model._meta.object_name,
ValueError: Cannot assign "1": "Shop.user" must be a "AuthUser" instance.
2017-05-19 16:42:15,492 [Thread-12:123145401339904] [django.request:152] [base:get_response] [WARNING]- Not Found: /gen204
2017-05-19 16:57:11,757 [Thread-13:123145454678016] [django.request:132] [exception:handle_uncaught_exception] [ERROR]- Internal Server Error: /cryapp/GoodIndexAdd/
Traceback (most recent call last):
  File "/Users/VANXV/.virtualenvs/zss322/lib/python3.6/site-packages/django/core/handlers/exception.py", line 42, in inner
    response = get_response(request)
  File "/Users/VANXV/.virtualenvs/zss322/lib/python3.6/site-packages/django/core/handlers/base.py", line 187, in _get_response
    response = self.process_exception_by_middleware(e, request)
  File "/Users/VANXV/.virtualenvs/zss322/lib/python3.6/site-packages/django/core/handlers/base.py", line 185, in _get_response
    response = wrapped_callback(request, *callback_args, **callback_kwargs)
  File "/Users/VANXV/.virtualenvs/zss322/lib/python3.6/site-packages/django/views/generic/base.py", line 68, in view
    return self.dispatch(request, *args, **kwargs)
  File "/Users/VANXV/.virtualenvs/zss322/lib/python3.6/site-packages/django/contrib/auth/mixins.py", line 56, in dispatch
    return super(LoginRequiredMixin, self).dispatch(request, *args, **kwargs)
  File "/Users/VANXV/.virtualenvs/zss322/lib/python3.6/site-packages/django/views/generic/base.py", line 88, in dispatch
    return handler(request, *args, **kwargs)
  File "/Users/VANXV/PycharmProjects/zss/cryapp/views.py", line 94, in post
    saveGoods = Goods.objects.create(user=request.user, shop='', name='', pgoods_id='', sendaddress='', platform='',image1='',keyword1='',price1='',remark1='')
  File "/Users/VANXV/.virtualenvs/zss322/lib/python3.6/site-packages/django/db/models/manager.py", line 85, in manager_method
    return getattr(self.get_queryset(), name)(*args, **kwargs)
  File "/Users/VANXV/.virtualenvs/zss322/lib/python3.6/site-packages/django/db/models/query.py", line 397, in create
    obj = self.model(**kwargs)
  File "/Users/VANXV/.virtualenvs/zss322/lib/python3.6/site-packages/django/db/models/base.py", line 537, in __init__
    setattr(self, field.name, rel_obj)
  File "/Users/VANXV/.virtualenvs/zss322/lib/python3.6/site-packages/django/db/models/fields/related_descriptors.py", line 211, in __set__
    self.field.remote_field.model._meta.object_name,
ValueError: Cannot assign "''": "Goods.shop" must be a "Shop" instance.
2017-05-19 17:12:18,011 [Thread-13:123145579266048] [django.request:132] [exception:handle_uncaught_exception] [ERROR]- Internal Server Error: /cryapp/GoodIndexAdd/
Traceback (most recent call last):
  File "/Users/VANXV/.virtualenvs/zss322/lib/python3.6/site-packages/django/core/handlers/exception.py", line 42, in inner
    response = get_response(request)
  File "/Users/VANXV/.virtualenvs/zss322/lib/python3.6/site-packages/django/core/handlers/base.py", line 187, in _get_response
    response = self.process_exception_by_middleware(e, request)
  File "/Users/VANXV/.virtualenvs/zss322/lib/python3.6/site-packages/django/core/handlers/base.py", line 185, in _get_response
    response = wrapped_callback(request, *callback_args, **callback_kwargs)
  File "/Users/VANXV/.virtualenvs/zss322/lib/python3.6/site-packages/django/views/generic/base.py", line 68, in view
    return self.dispatch(request, *args, **kwargs)
  File "/Users/VANXV/.virtualenvs/zss322/lib/python3.6/site-packages/django/contrib/auth/mixins.py", line 56, in dispatch
    return super(LoginRequiredMixin, self).dispatch(request, *args, **kwargs)
  File "/Users/VANXV/.virtualenvs/zss322/lib/python3.6/site-packages/django/views/generic/base.py", line 88, in dispatch
    return handler(request, *args, **kwargs)
  File "/Users/VANXV/PycharmProjects/zss/cryapp/views.py", line 93, in post
    saveGoods = Goods.objects.create(user=request.user, shop='', name=Goodsname, pgoods_id=id, sendaddress='', platform=platform,image1=GoodsImage,keyword1=keywords,price1=request.POST['money'],remark1=note)
  File "/Users/VANXV/.virtualenvs/zss322/lib/python3.6/site-packages/django/db/models/manager.py", line 85, in manager_method
    return getattr(self.get_queryset(), name)(*args, **kwargs)
  File "/Users/VANXV/.virtualenvs/zss322/lib/python3.6/site-packages/django/db/models/query.py", line 397, in create
    obj = self.model(**kwargs)
  File "/Users/VANXV/.virtualenvs/zss322/lib/python3.6/site-packages/django/db/models/base.py", line 537, in __init__
    setattr(self, field.name, rel_obj)
  File "/Users/VANXV/.virtualenvs/zss322/lib/python3.6/site-packages/django/db/models/fields/related_descriptors.py", line 211, in __set__
    self.field.remote_field.model._meta.object_name,
ValueError: Cannot assign "''": "Goods.shop" must be a "Shop" instance.
2017-05-19 17:43:18,551 [Thread-13:123145457811456] [django.request:132] [exception:handle_uncaught_exception] [ERROR]- Internal Server Error: /cryapp/GoodIndexAdd/
Traceback (most recent call last):
  File "/Users/VANXV/.virtualenvs/zss322/lib/python3.6/site-packages/django/core/handlers/exception.py", line 42, in inner
    response = get_response(request)
  File "/Users/VANXV/.virtualenvs/zss322/lib/python3.6/site-packages/django/core/handlers/base.py", line 187, in _get_response
    response = self.process_exception_by_middleware(e, request)
  File "/Users/VANXV/.virtualenvs/zss322/lib/python3.6/site-packages/django/core/handlers/base.py", line 185, in _get_response
    response = wrapped_callback(request, *callback_args, **callback_kwargs)
  File "/Users/VANXV/.virtualenvs/zss322/lib/python3.6/site-packages/django/views/generic/base.py", line 68, in view
    return self.dispatch(request, *args, **kwargs)
  File "/Users/VANXV/.virtualenvs/zss322/lib/python3.6/site-packages/django/contrib/auth/mixins.py", line 56, in dispatch
    return super(LoginRequiredMixin, self).dispatch(request, *args, **kwargs)
  File "/Users/VANXV/.virtualenvs/zss322/lib/python3.6/site-packages/django/views/generic/base.py", line 88, in dispatch
    return handler(request, *args, **kwargs)
  File "/Users/VANXV/PycharmProjects/zss/cryapp/views.py", line 96, in post
    savecryorder = CryOrder.objects.create(Userid=request.user, OrderSort='', Status= '', StartTime='', EndTime='', ShopId=saveshop, GoodId=saveGoods, Money=request.POST['money'], sendaddress='', platform=platform,image1=GoodsImage,Keywords=keywords,Note=note)
  File "/Users/VANXV/.virtualenvs/zss322/lib/python3.6/site-packages/django/db/models/manager.py", line 85, in manager_method
    return getattr(self.get_queryset(), name)(*args, **kwargs)
  File "/Users/VANXV/.virtualenvs/zss322/lib/python3.6/site-packages/django/db/models/query.py", line 397, in create
    obj = self.model(**kwargs)
  File "/Users/VANXV/.virtualenvs/zss322/lib/python3.6/site-packages/django/db/models/base.py", line 555, in __init__
    raise TypeError("'%s' is an invalid keyword argument for this function" % list(kwargs)[0])
TypeError: 'sendaddress' is an invalid keyword argument for this function
2017-05-19 17:44:47,865 [Thread-21:123145457811456] [django.request:132] [exception:handle_uncaught_exception] [ERROR]- Internal Server Error: /cryapp/GoodIndexAdd/
Traceback (most recent call last):
  File "/Users/VANXV/.virtualenvs/zss322/lib/python3.6/site-packages/django/core/handlers/exception.py", line 42, in inner
    response = get_response(request)
  File "/Users/VANXV/.virtualenvs/zss322/lib/python3.6/site-packages/django/core/handlers/base.py", line 187, in _get_response
    response = self.process_exception_by_middleware(e, request)
  File "/Users/VANXV/.virtualenvs/zss322/lib/python3.6/site-packages/django/core/handlers/base.py", line 185, in _get_response
    response = wrapped_callback(request, *callback_args, **callback_kwargs)
  File "/Users/VANXV/.virtualenvs/zss322/lib/python3.6/site-packages/django/views/generic/base.py", line 68, in view
    return self.dispatch(request, *args, **kwargs)
  File "/Users/VANXV/.virtualenvs/zss322/lib/python3.6/site-packages/django/contrib/auth/mixins.py", line 56, in dispatch
    return super(LoginRequiredMixin, self).dispatch(request, *args, **kwargs)
  File "/Users/VANXV/.virtualenvs/zss322/lib/python3.6/site-packages/django/views/generic/base.py", line 88, in dispatch
    return handler(request, *args, **kwargs)
  File "/Users/VANXV/PycharmProjects/zss/cryapp/views.py", line 96, in post
    savecryorder = CryOrder.objects.create(Userid=request.user, OrderSort='', Status= '', StartTime='', EndTime='', ShopId=saveshop, GoodId=saveGoods, Money=request.POST['money'], sendaddress='', platform=platform,image1=GoodsImage,Keywords=keywords,Note=note)
  File "/Users/VANXV/.virtualenvs/zss322/lib/python3.6/site-packages/django/db/models/manager.py", line 85, in manager_method
    return getattr(self.get_queryset(), name)(*args, **kwargs)
  File "/Users/VANXV/.virtualenvs/zss322/lib/python3.6/site-packages/django/db/models/query.py", line 397, in create
    obj = self.model(**kwargs)
  File "/Users/VANXV/.virtualenvs/zss322/lib/python3.6/site-packages/django/db/models/base.py", line 555, in __init__
    raise TypeError("'%s' is an invalid keyword argument for this function" % list(kwargs)[0])
TypeError: 'sendaddress' is an invalid keyword argument for this function
2017-05-19 17:47:14,432 [Thread-7:123145569394688] [django.request:132] [exception:handle_uncaught_exception] [ERROR]- Internal Server Error: /cryapp/GoodIndexAdd/
Traceback (most recent call last):
  File "/Users/VANXV/.virtualenvs/zss322/lib/python3.6/site-packages/django/core/handlers/exception.py", line 42, in inner
    response = get_response(request)
  File "/Users/VANXV/.virtualenvs/zss322/lib/python3.6/site-packages/django/core/handlers/base.py", line 187, in _get_response
    response = self.process_exception_by_middleware(e, request)
  File "/Users/VANXV/.virtualenvs/zss322/lib/python3.6/site-packages/django/core/handlers/base.py", line 185, in _get_response
    response = wrapped_callback(request, *callback_args, **callback_kwargs)
  File "/Users/VANXV/.virtualenvs/zss322/lib/python3.6/site-packages/django/views/generic/base.py", line 68, in view
    return self.dispatch(request, *args, **kwargs)
  File "/Users/VANXV/.virtualenvs/zss322/lib/python3.6/site-packages/django/contrib/auth/mixins.py", line 56, in dispatch
    return super(LoginRequiredMixin, self).dispatch(request, *args, **kwargs)
  File "/Users/VANXV/.virtualenvs/zss322/lib/python3.6/site-packages/django/views/generic/base.py", line 88, in dispatch
    return handler(request, *args, **kwargs)
  File "/Users/VANXV/PycharmProjects/zss/cryapp/views.py", line 96, in post
    savecryorder = CryOrder.objects.create(Userid=request.user, OrderSort='', Status= '', StartTime='', EndTime='', ShopId=saveshop, GoodId=saveGoods, Money=request.POST['money'], platform=platform,image1=GoodsImage,Keywords=keywords,Note=note)
  File "/Users/VANXV/.virtualenvs/zss322/lib/python3.6/site-packages/django/db/models/manager.py", line 85, in manager_method
    return getattr(self.get_queryset(), name)(*args, **kwargs)
  File "/Users/VANXV/.virtualenvs/zss322/lib/python3.6/site-packages/django/db/models/query.py", line 397, in create
    obj = self.model(**kwargs)
  File "/Users/VANXV/.virtualenvs/zss322/lib/python3.6/site-packages/django/db/models/base.py", line 555, in __init__
    raise TypeError("'%s' is an invalid keyword argument for this function" % list(kwargs)[0])
TypeError: 'image1' is an invalid keyword argument for this function
2017-05-19 17:48:56,999 [Thread-9:123145344344064] [django.request:132] [exception:handle_uncaught_exception] [ERROR]- Internal Server Error: /cryapp/GoodIndexAdd/
Traceback (most recent call last):
  File "/Users/VANXV/.virtualenvs/zss322/lib/python3.6/site-packages/django/core/handlers/exception.py", line 42, in inner
    response = get_response(request)
  File "/Users/VANXV/.virtualenvs/zss322/lib/python3.6/site-packages/django/core/handlers/base.py", line 187, in _get_response
    response = self.process_exception_by_middleware(e, request)
  File "/Users/VANXV/.virtualenvs/zss322/lib/python3.6/site-packages/django/core/handlers/base.py", line 185, in _get_response
    response = wrapped_callback(request, *callback_args, **callback_kwargs)
  File "/Users/VANXV/.virtualenvs/zss322/lib/python3.6/site-packages/django/views/generic/base.py", line 68, in view
    return self.dispatch(request, *args, **kwargs)
  File "/Users/VANXV/.virtualenvs/zss322/lib/python3.6/site-packages/django/contrib/auth/mixins.py", line 56, in dispatch
    return super(LoginRequiredMixin, self).dispatch(request, *args, **kwargs)
  File "/Users/VANXV/.virtualenvs/zss322/lib/python3.6/site-packages/django/views/generic/base.py", line 88, in dispatch
    return handler(request, *args, **kwargs)
  File "/Users/VANXV/PycharmProjects/zss/cryapp/views.py", line 96, in post
    savecryorder = CryOrder.objects.create(Userid=request.user, OrderSort='', Status= '', StartTime='', EndTime='', ShopId=saveshop, GoodId=saveGoods, Money=request.POST['money'], platform=platform, Keywords=keywords,Note=note)
  File "/Users/VANXV/.virtualenvs/zss322/lib/python3.6/site-packages/django/db/models/manager.py", line 85, in manager_method
    return getattr(self.get_queryset(), name)(*args, **kwargs)
  File "/Users/VANXV/.virtualenvs/zss322/lib/python3.6/site-packages/django/db/models/query.py", line 399, in create
    obj.save(force_insert=True, using=self.db)
  File "/Users/VANXV/.virtualenvs/zss322/lib/python3.6/site-packages/django/db/models/base.py", line 796, in save
    force_update=force_update, update_fields=update_fields)
  File "/Users/VANXV/.virtualenvs/zss322/lib/python3.6/site-packages/django/db/models/base.py", line 824, in save_base
    updated = self._save_table(raw, cls, force_insert, force_update, using, update_fields)
  File "/Users/VANXV/.virtualenvs/zss322/lib/python3.6/site-packages/django/db/models/base.py", line 908, in _save_table
    result = self._do_insert(cls._base_manager, using, fields, update_pk, raw)
  File "/Users/VANXV/.virtualenvs/zss322/lib/python3.6/site-packages/django/db/models/base.py", line 947, in _do_insert
    using=using, raw=raw)
  File "/Users/VANXV/.virtualenvs/zss322/lib/python3.6/site-packages/django/db/models/manager.py", line 85, in manager_method
    return getattr(self.get_queryset(), name)(*args, **kwargs)
  File "/Users/VANXV/.virtualenvs/zss322/lib/python3.6/site-packages/django/db/models/query.py", line 1045, in _insert
    return query.get_compiler(using=using).execute_sql(return_id)
  File "/Users/VANXV/.virtualenvs/zss322/lib/python3.6/site-packages/django/db/models/sql/compiler.py", line 1053, in execute_sql
    for sql, params in self.as_sql():
  File "/Users/VANXV/.virtualenvs/zss322/lib/python3.6/site-packages/django/db/models/sql/compiler.py", line 1006, in as_sql
    for obj in self.query.objs
  File "/Users/VANXV/.virtualenvs/zss322/lib/python3.6/site-packages/django/db/models/sql/compiler.py", line 1006, in <listcomp>
    for obj in self.query.objs
  File "/Users/VANXV/.virtualenvs/zss322/lib/python3.6/site-packages/django/db/models/sql/compiler.py", line 1005, in <listcomp>
    [self.prepare_value(field, self.pre_save_val(field, obj)) for field in fields]
  File "/Users/VANXV/.virtualenvs/zss322/lib/python3.6/site-packages/django/db/models/sql/compiler.py", line 945, in prepare_value
    value = field.get_db_prep_save(value, connection=self.connection)
  File "/Users/VANXV/.virtualenvs/zss322/lib/python3.6/site-packages/django/db/models/fields/__init__.py", line 755, in get_db_prep_save
    prepared=False)
  File "/Users/VANXV/.virtualenvs/zss322/lib/python3.6/site-packages/django/db/models/fields/__init__.py", line 747, in get_db_prep_value
    value = self.get_prep_value(value)
  File "/Users/VANXV/.virtualenvs/zss322/lib/python3.6/site-packages/django/db/models/fields/__init__.py", line 1832, in get_prep_value
    return int(value)
ValueError: invalid literal for int() with base 10: ''
2017-05-19 17:50:55,977 [Thread-13:123145357377536] [django.request:132] [exception:handle_uncaught_exception] [ERROR]- Internal Server Error: /cryapp/GoodIndexAdd/
Traceback (most recent call last):
  File "/Users/VANXV/.virtualenvs/zss322/lib/python3.6/site-packages/django/core/handlers/exception.py", line 42, in inner
    response = get_response(request)
  File "/Users/VANXV/.virtualenvs/zss322/lib/python3.6/site-packages/django/core/handlers/base.py", line 187, in _get_response
    response = self.process_exception_by_middleware(e, request)
  File "/Users/VANXV/.virtualenvs/zss322/lib/python3.6/site-packages/django/core/handlers/base.py", line 185, in _get_response
    response = wrapped_callback(request, *callback_args, **callback_kwargs)
  File "/Users/VANXV/.virtualenvs/zss322/lib/python3.6/site-packages/django/views/generic/base.py", line 68, in view
    return self.dispatch(request, *args, **kwargs)
  File "/Users/VANXV/.virtualenvs/zss322/lib/python3.6/site-packages/django/contrib/auth/mixins.py", line 56, in dispatch
    return super(LoginRequiredMixin, self).dispatch(request, *args, **kwargs)
  File "/Users/VANXV/.virtualenvs/zss322/lib/python3.6/site-packages/django/views/generic/base.py", line 88, in dispatch
    return handler(request, *args, **kwargs)
  File "/Users/VANXV/PycharmProjects/zss/cryapp/views.py", line 96, in post
    savecryorder = CryOrder.objects.create(Userid=request.user, OrderSort='', Status= '', StartTime='', EndTime='', ShopId=saveshop, GoodId=saveGoods, Money=request.POST['money'], platform=platform, Keywords=keywords,Note=note)
  File "/Users/VANXV/.virtualenvs/zss322/lib/python3.6/site-packages/django/db/models/manager.py", line 85, in manager_method
    return getattr(self.get_queryset(), name)(*args, **kwargs)
  File "/Users/VANXV/.virtualenvs/zss322/lib/python3.6/site-packages/django/db/models/query.py", line 399, in create
    obj.save(force_insert=True, using=self.db)
  File "/Users/VANXV/.virtualenvs/zss322/lib/python3.6/site-packages/django/db/models/base.py", line 796, in save
    force_update=force_update, update_fields=update_fields)
  File "/Users/VANXV/.virtualenvs/zss322/lib/python3.6/site-packages/django/db/models/base.py", line 824, in save_base
    updated = self._save_table(raw, cls, force_insert, force_update, using, update_fields)
  File "/Users/VANXV/.virtualenvs/zss322/lib/python3.6/site-packages/django/db/models/base.py", line 908, in _save_table
    result = self._do_insert(cls._base_manager, using, fields, update_pk, raw)
  File "/Users/VANXV/.virtualenvs/zss322/lib/python3.6/site-packages/django/db/models/base.py", line 947, in _do_insert
    using=using, raw=raw)
  File "/Users/VANXV/.virtualenvs/zss322/lib/python3.6/site-packages/django/db/models/manager.py", line 85, in manager_method
    return getattr(self.get_queryset(), name)(*args, **kwargs)
  File "/Users/VANXV/.virtualenvs/zss322/lib/python3.6/site-packages/django/db/models/query.py", line 1045, in _insert
    return query.get_compiler(using=using).execute_sql(return_id)
  File "/Users/VANXV/.virtualenvs/zss322/lib/python3.6/site-packages/django/db/models/sql/compiler.py", line 1053, in execute_sql
    for sql, params in self.as_sql():
  File "/Users/VANXV/.virtualenvs/zss322/lib/python3.6/site-packages/django/db/models/sql/compiler.py", line 1006, in as_sql
    for obj in self.query.objs
  File "/Users/VANXV/.virtualenvs/zss322/lib/python3.6/site-packages/django/db/models/sql/compiler.py", line 1006, in <listcomp>
    for obj in self.query.objs
  File "/Users/VANXV/.virtualenvs/zss322/lib/python3.6/site-packages/django/db/models/sql/compiler.py", line 1005, in <listcomp>
    [self.prepare_value(field, self.pre_save_val(field, obj)) for field in fields]
  File "/Users/VANXV/.virtualenvs/zss322/lib/python3.6/site-packages/django/db/models/sql/compiler.py", line 945, in prepare_value
    value = field.get_db_prep_save(value, connection=self.connection)
  File "/Users/VANXV/.virtualenvs/zss322/lib/python3.6/site-packages/django/db/models/fields/__init__.py", line 755, in get_db_prep_save
    prepared=False)
  File "/Users/VANXV/.virtualenvs/zss322/lib/python3.6/site-packages/django/db/models/fields/__init__.py", line 747, in get_db_prep_value
    value = self.get_prep_value(value)
  File "/Users/VANXV/.virtualenvs/zss322/lib/python3.6/site-packages/django/db/models/fields/__init__.py", line 1832, in get_prep_value
    return int(value)
ValueError: invalid literal for int() with base 10: ''
2017-05-19 18:10:55,461 [Thread-20:123145357377536] [django.request:132] [exception:handle_uncaught_exception] [ERROR]- Internal Server Error: /cryapp/GoodIndexAdd/
Traceback (most recent call last):
  File "/Users/VANXV/.virtualenvs/zss322/lib/python3.6/site-packages/django/core/handlers/exception.py", line 42, in inner
    response = get_response(request)
  File "/Users/VANXV/.virtualenvs/zss322/lib/python3.6/site-packages/django/core/handlers/base.py", line 187, in _get_response
    response = self.process_exception_by_middleware(e, request)
  File "/Users/VANXV/.virtualenvs/zss322/lib/python3.6/site-packages/django/core/handlers/base.py", line 185, in _get_response
    response = wrapped_callback(request, *callback_args, **callback_kwargs)
  File "/Users/VANXV/.virtualenvs/zss322/lib/python3.6/site-packages/django/views/generic/base.py", line 68, in view
    return self.dispatch(request, *args, **kwargs)
  File "/Users/VANXV/.virtualenvs/zss322/lib/python3.6/site-packages/django/contrib/auth/mixins.py", line 56, in dispatch
    return super(LoginRequiredMixin, self).dispatch(request, *args, **kwargs)
  File "/Users/VANXV/.virtualenvs/zss322/lib/python3.6/site-packages/django/views/generic/base.py", line 88, in dispatch
    return handler(request, *args, **kwargs)
  File "/Users/VANXV/PycharmProjects/zss/cryapp/views.py", line 96, in post
    savecryorder = CryOrder.objects.create(Userid=request.user, OrderSort='', Status= '', StartTime='', EndTime='', ShopId=saveshop, GoodId=saveGoods, Money=request.POST['money'], platform=platform, Keywords=keywords,Note=note)
  File "/Users/VANXV/.virtualenvs/zss322/lib/python3.6/site-packages/django/db/models/manager.py", line 85, in manager_method
    return getattr(self.get_queryset(), name)(*args, **kwargs)
  File "/Users/VANXV/.virtualenvs/zss322/lib/python3.6/site-packages/django/db/models/query.py", line 399, in create
    obj.save(force_insert=True, using=self.db)
  File "/Users/VANXV/.virtualenvs/zss322/lib/python3.6/site-packages/django/db/models/base.py", line 796, in save
    force_update=force_update, update_fields=update_fields)
  File "/Users/VANXV/.virtualenvs/zss322/lib/python3.6/site-packages/django/db/models/base.py", line 824, in save_base
    updated = self._save_table(raw, cls, force_insert, force_update, using, update_fields)
  File "/Users/VANXV/.virtualenvs/zss322/lib/python3.6/site-packages/django/db/models/base.py", line 908, in _save_table
    result = self._do_insert(cls._base_manager, using, fields, update_pk, raw)
  File "/Users/VANXV/.virtualenvs/zss322/lib/python3.6/site-packages/django/db/models/base.py", line 947, in _do_insert
    using=using, raw=raw)
  File "/Users/VANXV/.virtualenvs/zss322/lib/python3.6/site-packages/django/db/models/manager.py", line 85, in manager_method
    return getattr(self.get_queryset(), name)(*args, **kwargs)
  File "/Users/VANXV/.virtualenvs/zss322/lib/python3.6/site-packages/django/db/models/query.py", line 1045, in _insert
    return query.get_compiler(using=using).execute_sql(return_id)
  File "/Users/VANXV/.virtualenvs/zss322/lib/python3.6/site-packages/django/db/models/sql/compiler.py", line 1053, in execute_sql
    for sql, params in self.as_sql():
  File "/Users/VANXV/.virtualenvs/zss322/lib/python3.6/site-packages/django/db/models/sql/compiler.py", line 1006, in as_sql
    for obj in self.query.objs
  File "/Users/VANXV/.virtualenvs/zss322/lib/python3.6/site-packages/django/db/models/sql/compiler.py", line 1006, in <listcomp>
    for obj in self.query.objs
  File "/Users/VANXV/.virtualenvs/zss322/lib/python3.6/site-packages/django/db/models/sql/compiler.py", line 1005, in <listcomp>
    [self.prepare_value(field, self.pre_save_val(field, obj)) for field in fields]
  File "/Users/VANXV/.virtualenvs/zss322/lib/python3.6/site-packages/django/db/models/sql/compiler.py", line 945, in prepare_value
    value = field.get_db_prep_save(value, connection=self.connection)
  File "/Users/VANXV/.virtualenvs/zss322/lib/python3.6/site-packages/django/db/models/fields/__init__.py", line 755, in get_db_prep_save
    prepared=False)
  File "/Users/VANXV/.virtualenvs/zss322/lib/python3.6/site-packages/django/db/models/fields/__init__.py", line 747, in get_db_prep_value
    value = self.get_prep_value(value)
  File "/Users/VANXV/.virtualenvs/zss322/lib/python3.6/site-packages/django/db/models/fields/__init__.py", line 1832, in get_prep_value
    return int(value)
ValueError: invalid literal for int() with base 10: ''
2017-05-19 19:50:26,698 [Thread-13:123145595351040] [django.request:132] [exception:handle_uncaught_exception] [ERROR]- Internal Server Error: /cryapp/GoodIndexAdd/
Traceback (most recent call last):
  File "/Users/VANXV/.virtualenvs/zss322/lib/python3.6/site-packages/django/db/backends/utils.py", line 64, in execute
    return self.cursor.execute(sql, params)
  File "/Users/VANXV/.virtualenvs/zss322/lib/python3.6/site-packages/django/db/backends/mysql/base.py", line 110, in execute
    return self.cursor.execute(query, args)
  File "/Users/VANXV/.virtualenvs/zss322/lib/python3.6/site-packages/pymysql/cursors.py", line 166, in execute
    result = self._query(query)
  File "/Users/VANXV/.virtualenvs/zss322/lib/python3.6/site-packages/pymysql/cursors.py", line 322, in _query
    conn.query(q)
  File "/Users/VANXV/.virtualenvs/zss322/lib/python3.6/site-packages/pymysql/connections.py", line 852, in query
    self._affected_rows = self._read_query_result(unbuffered=unbuffered)
  File "/Users/VANXV/.virtualenvs/zss322/lib/python3.6/site-packages/pymysql/connections.py", line 1053, in _read_query_result
    result.read()
  File "/Users/VANXV/.virtualenvs/zss322/lib/python3.6/site-packages/pymysql/connections.py", line 1336, in read
    first_packet = self.connection._read_packet()
  File "/Users/VANXV/.virtualenvs/zss322/lib/python3.6/site-packages/pymysql/connections.py", line 1010, in _read_packet
    packet.check_error()
  File "/Users/VANXV/.virtualenvs/zss322/lib/python3.6/site-packages/pymysql/connections.py", line 393, in check_error
    err.raise_mysql_exception(self._data)
  File "/Users/VANXV/.virtualenvs/zss322/lib/python3.6/site-packages/pymysql/err.py", line 107, in raise_mysql_exception
    raise errorclass(errno, errval)
pymysql.err.IntegrityError: (1048, "Column 'OrderSort' cannot be null")

The above exception was the direct cause of the following exception:

Traceback (most recent call last):
  File "/Users/VANXV/.virtualenvs/zss322/lib/python3.6/site-packages/django/core/handlers/exception.py", line 42, in inner
    response = get_response(request)
  File "/Users/VANXV/.virtualenvs/zss322/lib/python3.6/site-packages/django/core/handlers/base.py", line 187, in _get_response
    response = self.process_exception_by_middleware(e, request)
  File "/Users/VANXV/.virtualenvs/zss322/lib/python3.6/site-packages/django/core/handlers/base.py", line 185, in _get_response
    response = wrapped_callback(request, *callback_args, **callback_kwargs)
  File "/Users/VANXV/.virtualenvs/zss322/lib/python3.6/site-packages/django/views/generic/base.py", line 68, in view
    return self.dispatch(request, *args, **kwargs)
  File "/Users/VANXV/.virtualenvs/zss322/lib/python3.6/site-packages/django/contrib/auth/mixins.py", line 56, in dispatch
    return super(LoginRequiredMixin, self).dispatch(request, *args, **kwargs)
  File "/Users/VANXV/.virtualenvs/zss322/lib/python3.6/site-packages/django/views/generic/base.py", line 88, in dispatch
    return handler(request, *args, **kwargs)
  File "/Users/VANXV/PycharmProjects/zss/cryapp/views.py", line 96, in post
    savecryorder = CryOrder.objects.create(Userid=request.user,ShopId=saveshop, GoodId=saveGoods, Money=request.POST['money'], platform=platform, Keywords=keywords,Note=note)
  File "/Users/VANXV/.virtualenvs/zss322/lib/python3.6/site-packages/django/db/models/manager.py", line 85, in manager_method
    return getattr(self.get_queryset(), name)(*args, **kwargs)
  File "/Users/VANXV/.virtualenvs/zss322/lib/python3.6/site-packages/django/db/models/query.py", line 399, in create
    obj.save(force_insert=True, using=self.db)
  File "/Users/VANXV/.virtualenvs/zss322/lib/python3.6/site-packages/django/db/models/base.py", line 796, in save
    force_update=force_update, update_fields=update_fields)
  File "/Users/VANXV/.virtualenvs/zss322/lib/python3.6/site-packages/django/db/models/base.py", line 824, in save_base
    updated = self._save_table(raw, cls, force_insert, force_update, using, update_fields)
  File "/Users/VANXV/.virtualenvs/zss322/lib/python3.6/site-packages/django/db/models/base.py", line 908, in _save_table
    result = self._do_insert(cls._base_manager, using, fields, update_pk, raw)
  File "/Users/VANXV/.virtualenvs/zss322/lib/python3.6/site-packages/django/db/models/base.py", line 947, in _do_insert
    using=using, raw=raw)
  File "/Users/VANXV/.virtualenvs/zss322/lib/python3.6/site-packages/django/db/models/manager.py", line 85, in manager_method
    return getattr(self.get_queryset(), name)(*args, **kwargs)
  File "/Users/VANXV/.virtualenvs/zss322/lib/python3.6/site-packages/django/db/models/query.py", line 1045, in _insert
    return query.get_compiler(using=using).execute_sql(return_id)
  File "/Users/VANXV/.virtualenvs/zss322/lib/python3.6/site-packages/django/db/models/sql/compiler.py", line 1054, in execute_sql
    cursor.execute(sql, params)
  File "/Users/VANXV/.virtualenvs/zss322/lib/python3.6/site-packages/django/db/backends/utils.py", line 79, in execute
    return super(CursorDebugWrapper, self).execute(sql, params)
  File "/Users/VANXV/.virtualenvs/zss322/lib/python3.6/site-packages/django/db/backends/utils.py", line 64, in execute
    return self.cursor.execute(sql, params)
  File "/Users/VANXV/.virtualenvs/zss322/lib/python3.6/site-packages/django/db/utils.py", line 94, in __exit__
    six.reraise(dj_exc_type, dj_exc_value, traceback)
  File "/Users/VANXV/.virtualenvs/zss322/lib/python3.6/site-packages/django/utils/six.py", line 685, in reraise
    raise value.with_traceback(tb)
  File "/Users/VANXV/.virtualenvs/zss322/lib/python3.6/site-packages/django/db/backends/utils.py", line 64, in execute
    return self.cursor.execute(sql, params)
  File "/Users/VANXV/.virtualenvs/zss322/lib/python3.6/site-packages/django/db/backends/mysql/base.py", line 110, in execute
    return self.cursor.execute(query, args)
  File "/Users/VANXV/.virtualenvs/zss322/lib/python3.6/site-packages/pymysql/cursors.py", line 166, in execute
    result = self._query(query)
  File "/Users/VANXV/.virtualenvs/zss322/lib/python3.6/site-packages/pymysql/cursors.py", line 322, in _query
    conn.query(q)
  File "/Users/VANXV/.virtualenvs/zss322/lib/python3.6/site-packages/pymysql/connections.py", line 852, in query
    self._affected_rows = self._read_query_result(unbuffered=unbuffered)
  File "/Users/VANXV/.virtualenvs/zss322/lib/python3.6/site-packages/pymysql/connections.py", line 1053, in _read_query_result
    result.read()
  File "/Users/VANXV/.virtualenvs/zss322/lib/python3.6/site-packages/pymysql/connections.py", line 1336, in read
    first_packet = self.connection._read_packet()
  File "/Users/VANXV/.virtualenvs/zss322/lib/python3.6/site-packages/pymysql/connections.py", line 1010, in _read_packet
    packet.check_error()
  File "/Users/VANXV/.virtualenvs/zss322/lib/python3.6/site-packages/pymysql/connections.py", line 393, in check_error
    err.raise_mysql_exception(self._data)
  File "/Users/VANXV/.virtualenvs/zss322/lib/python3.6/site-packages/pymysql/err.py", line 107, in raise_mysql_exception
    raise errorclass(errno, errval)
django.db.utils.IntegrityError: (1048, "Column 'OrderSort' cannot be null")
2017-05-19 19:58:22,589 [Thread-9:123145532182528] [django.request:132] [exception:handle_uncaught_exception] [ERROR]- Internal Server Error: /cryapp/GoodIndexAdd/
Traceback (most recent call last):
  File "/Users/VANXV/.virtualenvs/zss322/lib/python3.6/site-packages/django/db/backends/utils.py", line 64, in execute
    return self.cursor.execute(sql, params)
  File "/Users/VANXV/.virtualenvs/zss322/lib/python3.6/site-packages/django/db/backends/mysql/base.py", line 110, in execute
    return self.cursor.execute(query, args)
  File "/Users/VANXV/.virtualenvs/zss322/lib/python3.6/site-packages/pymysql/cursors.py", line 166, in execute
    result = self._query(query)
  File "/Users/VANXV/.virtualenvs/zss322/lib/python3.6/site-packages/pymysql/cursors.py", line 322, in _query
    conn.query(q)
  File "/Users/VANXV/.virtualenvs/zss322/lib/python3.6/site-packages/pymysql/connections.py", line 852, in query
    self._affected_rows = self._read_query_result(unbuffered=unbuffered)
  File "/Users/VANXV/.virtualenvs/zss322/lib/python3.6/site-packages/pymysql/connections.py", line 1053, in _read_query_result
    result.read()
  File "/Users/VANXV/.virtualenvs/zss322/lib/python3.6/site-packages/pymysql/connections.py", line 1336, in read
    first_packet = self.connection._read_packet()
  File "/Users/VANXV/.virtualenvs/zss322/lib/python3.6/site-packages/pymysql/connections.py", line 1010, in _read_packet
    packet.check_error()
  File "/Users/VANXV/.virtualenvs/zss322/lib/python3.6/site-packages/pymysql/connections.py", line 393, in check_error
    err.raise_mysql_exception(self._data)
  File "/Users/VANXV/.virtualenvs/zss322/lib/python3.6/site-packages/pymysql/err.py", line 107, in raise_mysql_exception
    raise errorclass(errno, errval)
pymysql.err.IntegrityError: (1048, "Column 'Status' cannot be null")

The above exception was the direct cause of the following exception:

Traceback (most recent call last):
  File "/Users/VANXV/.virtualenvs/zss322/lib/python3.6/site-packages/django/core/handlers/exception.py", line 42, in inner
    response = get_response(request)
  File "/Users/VANXV/.virtualenvs/zss322/lib/python3.6/site-packages/django/core/handlers/base.py", line 187, in _get_response
    response = self.process_exception_by_middleware(e, request)
  File "/Users/VANXV/.virtualenvs/zss322/lib/python3.6/site-packages/django/core/handlers/base.py", line 185, in _get_response
    response = wrapped_callback(request, *callback_args, **callback_kwargs)
  File "/Users/VANXV/.virtualenvs/zss322/lib/python3.6/site-packages/django/views/generic/base.py", line 68, in view
    return self.dispatch(request, *args, **kwargs)
  File "/Users/VANXV/.virtualenvs/zss322/lib/python3.6/site-packages/django/contrib/auth/mixins.py", line 56, in dispatch
    return super(LoginRequiredMixin, self).dispatch(request, *args, **kwargs)
  File "/Users/VANXV/.virtualenvs/zss322/lib/python3.6/site-packages/django/views/generic/base.py", line 88, in dispatch
    return handler(request, *args, **kwargs)
  File "/Users/VANXV/PycharmProjects/zss/cryapp/views.py", line 96, in post
    savecryorder = CryOrder.objects.create(Userid=request.user,ShopId=saveshop, GoodId=saveGoods, Money=request.POST['money'], platform=platform, Keywords=keywords,Note=note)
  File "/Users/VANXV/.virtualenvs/zss322/lib/python3.6/site-packages/django/db/models/manager.py", line 85, in manager_method
    return getattr(self.get_queryset(), name)(*args, **kwargs)
  File "/Users/VANXV/.virtualenvs/zss322/lib/python3.6/site-packages/django/db/models/query.py", line 399, in create
    obj.save(force_insert=True, using=self.db)
  File "/Users/VANXV/.virtualenvs/zss322/lib/python3.6/site-packages/django/db/models/base.py", line 796, in save
    force_update=force_update, update_fields=update_fields)
  File "/Users/VANXV/.virtualenvs/zss322/lib/python3.6/site-packages/django/db/models/base.py", line 824, in save_base
    updated = self._save_table(raw, cls, force_insert, force_update, using, update_fields)
  File "/Users/VANXV/.virtualenvs/zss322/lib/python3.6/site-packages/django/db/models/base.py", line 908, in _save_table
    result = self._do_insert(cls._base_manager, using, fields, update_pk, raw)
  File "/Users/VANXV/.virtualenvs/zss322/lib/python3.6/site-packages/django/db/models/base.py", line 947, in _do_insert
    using=using, raw=raw)
  File "/Users/VANXV/.virtualenvs/zss322/lib/python3.6/site-packages/django/db/models/manager.py", line 85, in manager_method
    return getattr(self.get_queryset(), name)(*args, **kwargs)
  File "/Users/VANXV/.virtualenvs/zss322/lib/python3.6/site-packages/django/db/models/query.py", line 1045, in _insert
    return query.get_compiler(using=using).execute_sql(return_id)
  File "/Users/VANXV/.virtualenvs/zss322/lib/python3.6/site-packages/django/db/models/sql/compiler.py", line 1054, in execute_sql
    cursor.execute(sql, params)
  File "/Users/VANXV/.virtualenvs/zss322/lib/python3.6/site-packages/django/db/backends/utils.py", line 79, in execute
    return super(CursorDebugWrapper, self).execute(sql, params)
  File "/Users/VANXV/.virtualenvs/zss322/lib/python3.6/site-packages/django/db/backends/utils.py", line 64, in execute
    return self.cursor.execute(sql, params)
  File "/Users/VANXV/.virtualenvs/zss322/lib/python3.6/site-packages/django/db/utils.py", line 94, in __exit__
    six.reraise(dj_exc_type, dj_exc_value, traceback)
  File "/Users/VANXV/.virtualenvs/zss322/lib/python3.6/site-packages/django/utils/six.py", line 685, in reraise
    raise value.with_traceback(tb)
  File "/Users/VANXV/.virtualenvs/zss322/lib/python3.6/site-packages/django/db/backends/utils.py", line 64, in execute
    return self.cursor.execute(sql, params)
  File "/Users/VANXV/.virtualenvs/zss322/lib/python3.6/site-packages/django/db/backends/mysql/base.py", line 110, in execute
    return self.cursor.execute(query, args)
  File "/Users/VANXV/.virtualenvs/zss322/lib/python3.6/site-packages/pymysql/cursors.py", line 166, in execute
    result = self._query(query)
  File "/Users/VANXV/.virtualenvs/zss322/lib/python3.6/site-packages/pymysql/cursors.py", line 322, in _query
    conn.query(q)
  File "/Users/VANXV/.virtualenvs/zss322/lib/python3.6/site-packages/pymysql/connections.py", line 852, in query
    self._affected_rows = self._read_query_result(unbuffered=unbuffered)
  File "/Users/VANXV/.virtualenvs/zss322/lib/python3.6/site-packages/pymysql/connections.py", line 1053, in _read_query_result
    result.read()
  File "/Users/VANXV/.virtualenvs/zss322/lib/python3.6/site-packages/pymysql/connections.py", line 1336, in read
    first_packet = self.connection._read_packet()
  File "/Users/VANXV/.virtualenvs/zss322/lib/python3.6/site-packages/pymysql/connections.py", line 1010, in _read_packet
    packet.check_error()
  File "/Users/VANXV/.virtualenvs/zss322/lib/python3.6/site-packages/pymysql/connections.py", line 393, in check_error
    err.raise_mysql_exception(self._data)
  File "/Users/VANXV/.virtualenvs/zss322/lib/python3.6/site-packages/pymysql/err.py", line 107, in raise_mysql_exception
    raise errorclass(errno, errval)
django.db.utils.IntegrityError: (1048, "Column 'Status' cannot be null")
2017-05-19 19:59:32,863 [Thread-13:123145535344640] [django.request:132] [exception:handle_uncaught_exception] [ERROR]- Internal Server Error: /cryapp/GoodIndexAdd/
Traceback (most recent call last):
  File "/Users/VANXV/.virtualenvs/zss322/lib/python3.6/site-packages/django/db/backends/utils.py", line 64, in execute
    return self.cursor.execute(sql, params)
  File "/Users/VANXV/.virtualenvs/zss322/lib/python3.6/site-packages/django/db/backends/mysql/base.py", line 110, in execute
    return self.cursor.execute(query, args)
  File "/Users/VANXV/.virtualenvs/zss322/lib/python3.6/site-packages/pymysql/cursors.py", line 166, in execute
    result = self._query(query)
  File "/Users/VANXV/.virtualenvs/zss322/lib/python3.6/site-packages/pymysql/cursors.py", line 322, in _query
    conn.query(q)
  File "/Users/VANXV/.virtualenvs/zss322/lib/python3.6/site-packages/pymysql/connections.py", line 852, in query
    self._affected_rows = self._read_query_result(unbuffered=unbuffered)
  File "/Users/VANXV/.virtualenvs/zss322/lib/python3.6/site-packages/pymysql/connections.py", line 1053, in _read_query_result
    result.read()
  File "/Users/VANXV/.virtualenvs/zss322/lib/python3.6/site-packages/pymysql/connections.py", line 1336, in read
    first_packet = self.connection._read_packet()
  File "/Users/VANXV/.virtualenvs/zss322/lib/python3.6/site-packages/pymysql/connections.py", line 1010, in _read_packet
    packet.check_error()
  File "/Users/VANXV/.virtualenvs/zss322/lib/python3.6/site-packages/pymysql/connections.py", line 393, in check_error
    err.raise_mysql_exception(self._data)
  File "/Users/VANXV/.virtualenvs/zss322/lib/python3.6/site-packages/pymysql/err.py", line 107, in raise_mysql_exception
    raise errorclass(errno, errval)
pymysql.err.IntegrityError: (1048, "Column 'StartTime' cannot be null")

The above exception was the direct cause of the following exception:

Traceback (most recent call last):
  File "/Users/VANXV/.virtualenvs/zss322/lib/python3.6/site-packages/django/core/handlers/exception.py", line 42, in inner
    response = get_response(request)
  File "/Users/VANXV/.virtualenvs/zss322/lib/python3.6/site-packages/django/core/handlers/base.py", line 187, in _get_response
    response = self.process_exception_by_middleware(e, request)
  File "/Users/VANXV/.virtualenvs/zss322/lib/python3.6/site-packages/django/core/handlers/base.py", line 185, in _get_response
    response = wrapped_callback(request, *callback_args, **callback_kwargs)
  File "/Users/VANXV/.virtualenvs/zss322/lib/python3.6/site-packages/django/views/generic/base.py", line 68, in view
    return self.dispatch(request, *args, **kwargs)
  File "/Users/VANXV/.virtualenvs/zss322/lib/python3.6/site-packages/django/contrib/auth/mixins.py", line 56, in dispatch
    return super(LoginRequiredMixin, self).dispatch(request, *args, **kwargs)
  File "/Users/VANXV/.virtualenvs/zss322/lib/python3.6/site-packages/django/views/generic/base.py", line 88, in dispatch
    return handler(request, *args, **kwargs)
  File "/Users/VANXV/PycharmProjects/zss/cryapp/views.py", line 96, in post
    savecryorder = CryOrder.objects.create(Userid=request.user,ShopId=saveshop, Status='1', GoodId=saveGoods, Money=request.POST['money'], platform=platform, Keywords=keywords,Note=note)
  File "/Users/VANXV/.virtualenvs/zss322/lib/python3.6/site-packages/django/db/models/manager.py", line 85, in manager_method
    return getattr(self.get_queryset(), name)(*args, **kwargs)
  File "/Users/VANXV/.virtualenvs/zss322/lib/python3.6/site-packages/django/db/models/query.py", line 399, in create
    obj.save(force_insert=True, using=self.db)
  File "/Users/VANXV/.virtualenvs/zss322/lib/python3.6/site-packages/django/db/models/base.py", line 796, in save
    force_update=force_update, update_fields=update_fields)
  File "/Users/VANXV/.virtualenvs/zss322/lib/python3.6/site-packages/django/db/models/base.py", line 824, in save_base
    updated = self._save_table(raw, cls, force_insert, force_update, using, update_fields)
  File "/Users/VANXV/.virtualenvs/zss322/lib/python3.6/site-packages/django/db/models/base.py", line 908, in _save_table
    result = self._do_insert(cls._base_manager, using, fields, update_pk, raw)
  File "/Users/VANXV/.virtualenvs/zss322/lib/python3.6/site-packages/django/db/models/base.py", line 947, in _do_insert
    using=using, raw=raw)
  File "/Users/VANXV/.virtualenvs/zss322/lib/python3.6/site-packages/django/db/models/manager.py", line 85, in manager_method
    return getattr(self.get_queryset(), name)(*args, **kwargs)
  File "/Users/VANXV/.virtualenvs/zss322/lib/python3.6/site-packages/django/db/models/query.py", line 1045, in _insert
    return query.get_compiler(using=using).execute_sql(return_id)
  File "/Users/VANXV/.virtualenvs/zss322/lib/python3.6/site-packages/django/db/models/sql/compiler.py", line 1054, in execute_sql
    cursor.execute(sql, params)
  File "/Users/VANXV/.virtualenvs/zss322/lib/python3.6/site-packages/django/db/backends/utils.py", line 79, in execute
    return super(CursorDebugWrapper, self).execute(sql, params)
  File "/Users/VANXV/.virtualenvs/zss322/lib/python3.6/site-packages/django/db/backends/utils.py", line 64, in execute
    return self.cursor.execute(sql, params)
  File "/Users/VANXV/.virtualenvs/zss322/lib/python3.6/site-packages/django/db/utils.py", line 94, in __exit__
    six.reraise(dj_exc_type, dj_exc_value, traceback)
  File "/Users/VANXV/.virtualenvs/zss322/lib/python3.6/site-packages/django/utils/six.py", line 685, in reraise
    raise value.with_traceback(tb)
  File "/Users/VANXV/.virtualenvs/zss322/lib/python3.6/site-packages/django/db/backends/utils.py", line 64, in execute
    return self.cursor.execute(sql, params)
  File "/Users/VANXV/.virtualenvs/zss322/lib/python3.6/site-packages/django/db/backends/mysql/base.py", line 110, in execute
    return self.cursor.execute(query, args)
  File "/Users/VANXV/.virtualenvs/zss322/lib/python3.6/site-packages/pymysql/cursors.py", line 166, in execute
    result = self._query(query)
  File "/Users/VANXV/.virtualenvs/zss322/lib/python3.6/site-packages/pymysql/cursors.py", line 322, in _query
    conn.query(q)
  File "/Users/VANXV/.virtualenvs/zss322/lib/python3.6/site-packages/pymysql/connections.py", line 852, in query
    self._affected_rows = self._read_query_result(unbuffered=unbuffered)
  File "/Users/VANXV/.virtualenvs/zss322/lib/python3.6/site-packages/pymysql/connections.py", line 1053, in _read_query_result
    result.read()
  File "/Users/VANXV/.virtualenvs/zss322/lib/python3.6/site-packages/pymysql/connections.py", line 1336, in read
    first_packet = self.connection._read_packet()
  File "/Users/VANXV/.virtualenvs/zss322/lib/python3.6/site-packages/pymysql/connections.py", line 1010, in _read_packet
    packet.check_error()
  File "/Users/VANXV/.virtualenvs/zss322/lib/python3.6/site-packages/pymysql/connections.py", line 393, in check_error
    err.raise_mysql_exception(self._data)
  File "/Users/VANXV/.virtualenvs/zss322/lib/python3.6/site-packages/pymysql/err.py", line 107, in raise_mysql_exception
    raise errorclass(errno, errval)
django.db.utils.IntegrityError: (1048, "Column 'StartTime' cannot be null")
2017-05-19 20:23:34,373 [Thread-14:123145590484992] [django.request:132] [exception:handle_uncaught_exception] [ERROR]- Internal Server Error: /cryapp/GoodIndexAdd/
Traceback (most recent call last):
  File "/Users/VANXV/.virtualenvs/zss322/lib/python3.6/site-packages/django/core/handlers/exception.py", line 42, in inner
    response = get_response(request)
  File "/Users/VANXV/.virtualenvs/zss322/lib/python3.6/site-packages/django/core/handlers/base.py", line 187, in _get_response
    response = self.process_exception_by_middleware(e, request)
  File "/Users/VANXV/.virtualenvs/zss322/lib/python3.6/site-packages/django/core/handlers/base.py", line 185, in _get_response
    response = wrapped_callback(request, *callback_args, **callback_kwargs)
  File "/Users/VANXV/.virtualenvs/zss322/lib/python3.6/site-packages/django/views/generic/base.py", line 68, in view
    return self.dispatch(request, *args, **kwargs)
  File "/Users/VANXV/.virtualenvs/zss322/lib/python3.6/site-packages/django/contrib/auth/mixins.py", line 56, in dispatch
    return super(LoginRequiredMixin, self).dispatch(request, *args, **kwargs)
  File "/Users/VANXV/.virtualenvs/zss322/lib/python3.6/site-packages/django/views/generic/base.py", line 88, in dispatch
    return handler(request, *args, **kwargs)
  File "/Users/VANXV/PycharmProjects/zss/cryapp/views.py", line 86, in post
    savecryorder = CryOrder.objects.create(Userid=request.user,ShopId=saveshop, Status='1', GoodId=saveGoods, StartTime=startdatetime, EndTime=endDateTime,  platform=platform, Keywords=keywords,Note=note, Money=request.POST['money'])
  File "/Users/VANXV/.virtualenvs/zss322/lib/python3.6/site-packages/django/db/models/manager.py", line 85, in manager_method
    return getattr(self.get_queryset(), name)(*args, **kwargs)
  File "/Users/VANXV/.virtualenvs/zss322/lib/python3.6/site-packages/django/db/models/query.py", line 397, in create
    obj = self.model(**kwargs)
  File "/Users/VANXV/.virtualenvs/zss322/lib/python3.6/site-packages/django/db/models/base.py", line 537, in __init__
    setattr(self, field.name, rel_obj)
  File "/Users/VANXV/.virtualenvs/zss322/lib/python3.6/site-packages/django/db/models/fields/related_descriptors.py", line 211, in __set__
    self.field.remote_field.model._meta.object_name,
ValueError: Cannot assign "<QuerySet []>": "CryOrder.GoodId" must be a "Goods" instance.
2017-05-19 20:32:42,610 [Thread-9:123145550409728] [django.request:132] [exception:handle_uncaught_exception] [ERROR]- Internal Server Error: /cryapp/GoodIndexAdd/
Traceback (most recent call last):
  File "/Users/VANXV/.virtualenvs/zss322/lib/python3.6/site-packages/django/core/handlers/exception.py", line 42, in inner
    response = get_response(request)
  File "/Users/VANXV/.virtualenvs/zss322/lib/python3.6/site-packages/django/core/handlers/base.py", line 187, in _get_response
    response = self.process_exception_by_middleware(e, request)
  File "/Users/VANXV/.virtualenvs/zss322/lib/python3.6/site-packages/django/core/handlers/base.py", line 185, in _get_response
    response = wrapped_callback(request, *callback_args, **callback_kwargs)
  File "/Users/VANXV/.virtualenvs/zss322/lib/python3.6/site-packages/django/views/generic/base.py", line 68, in view
    return self.dispatch(request, *args, **kwargs)
  File "/Users/VANXV/.virtualenvs/zss322/lib/python3.6/site-packages/django/contrib/auth/mixins.py", line 56, in dispatch
    return super(LoginRequiredMixin, self).dispatch(request, *args, **kwargs)
  File "/Users/VANXV/.virtualenvs/zss322/lib/python3.6/site-packages/django/views/generic/base.py", line 88, in dispatch
    return handler(request, *args, **kwargs)
  File "/Users/VANXV/PycharmProjects/zss/cryapp/views.py", line 86, in post
    savecryorder = CryOrder.objects.create(Userid=request.user,ShopId=saveshop, Status='1', GoodId=saveGoods, StartTime=startdatetime, EndTime=endDateTime,  platform=platform, Keywords=keywords,Note=note, Money=request.POST['money'])
  File "/Users/VANXV/.virtualenvs/zss322/lib/python3.6/site-packages/django/db/models/manager.py", line 85, in manager_method
    return getattr(self.get_queryset(), name)(*args, **kwargs)
  File "/Users/VANXV/.virtualenvs/zss322/lib/python3.6/site-packages/django/db/models/query.py", line 397, in create
    obj = self.model(**kwargs)
  File "/Users/VANXV/.virtualenvs/zss322/lib/python3.6/site-packages/django/db/models/base.py", line 537, in __init__
    setattr(self, field.name, rel_obj)
  File "/Users/VANXV/.virtualenvs/zss322/lib/python3.6/site-packages/django/db/models/fields/related_descriptors.py", line 211, in __set__
    self.field.remote_field.model._meta.object_name,
ValueError: Cannot assign "<QuerySet []>": "CryOrder.GoodId" must be a "Goods" instance.
2017-05-19 20:33:34,179 [Thread-16:123145550409728] [django.request:132] [exception:handle_uncaught_exception] [ERROR]- Internal Server Error: /cryapp/GoodIndexAdd/
Traceback (most recent call last):
  File "/Users/VANXV/.virtualenvs/zss322/lib/python3.6/site-packages/django/core/handlers/exception.py", line 42, in inner
    response = get_response(request)
  File "/Users/VANXV/.virtualenvs/zss322/lib/python3.6/site-packages/django/core/handlers/base.py", line 187, in _get_response
    response = self.process_exception_by_middleware(e, request)
  File "/Users/VANXV/.virtualenvs/zss322/lib/python3.6/site-packages/django/core/handlers/base.py", line 185, in _get_response
    response = wrapped_callback(request, *callback_args, **callback_kwargs)
  File "/Users/VANXV/.virtualenvs/zss322/lib/python3.6/site-packages/django/views/generic/base.py", line 68, in view
    return self.dispatch(request, *args, **kwargs)
  File "/Users/VANXV/.virtualenvs/zss322/lib/python3.6/site-packages/django/contrib/auth/mixins.py", line 56, in dispatch
    return super(LoginRequiredMixin, self).dispatch(request, *args, **kwargs)
  File "/Users/VANXV/.virtualenvs/zss322/lib/python3.6/site-packages/django/views/generic/base.py", line 88, in dispatch
    return handler(request, *args, **kwargs)
  File "/Users/VANXV/PycharmProjects/zss/cryapp/views.py", line 86, in post
    savecryorder = CryOrder.objects.create(Userid=request.user,ShopId=saveshop, Status='1', GoodId=saveGoods, StartTime=startdatetime, EndTime=endDateTime,  platform=platform, Keywords=keywords,Note=note, Money=request.POST['money'])
  File "/Users/VANXV/.virtualenvs/zss322/lib/python3.6/site-packages/django/db/models/manager.py", line 85, in manager_method
    return getattr(self.get_queryset(), name)(*args, **kwargs)
  File "/Users/VANXV/.virtualenvs/zss322/lib/python3.6/site-packages/django/db/models/query.py", line 397, in create
    obj = self.model(**kwargs)
  File "/Users/VANXV/.virtualenvs/zss322/lib/python3.6/site-packages/django/db/models/base.py", line 537, in __init__
    setattr(self, field.name, rel_obj)
  File "/Users/VANXV/.virtualenvs/zss322/lib/python3.6/site-packages/django/db/models/fields/related_descriptors.py", line 211, in __set__
    self.field.remote_field.model._meta.object_name,
ValueError: Cannot assign "<QuerySet []>": "CryOrder.GoodId" must be a "Goods" instance.
2017-05-19 20:35:15,206 [Thread-13:123145559347200] [django.request:132] [exception:handle_uncaught_exception] [ERROR]- Internal Server Error: /cryapp/GoodIndexAdd/
Traceback (most recent call last):
  File "/Users/VANXV/.virtualenvs/zss322/lib/python3.6/site-packages/django/core/handlers/exception.py", line 42, in inner
    response = get_response(request)
  File "/Users/VANXV/.virtualenvs/zss322/lib/python3.6/site-packages/django/core/handlers/base.py", line 187, in _get_response
    response = self.process_exception_by_middleware(e, request)
  File "/Users/VANXV/.virtualenvs/zss322/lib/python3.6/site-packages/django/core/handlers/base.py", line 185, in _get_response
    response = wrapped_callback(request, *callback_args, **callback_kwargs)
  File "/Users/VANXV/.virtualenvs/zss322/lib/python3.6/site-packages/django/views/generic/base.py", line 68, in view
    return self.dispatch(request, *args, **kwargs)
  File "/Users/VANXV/.virtualenvs/zss322/lib/python3.6/site-packages/django/contrib/auth/mixins.py", line 56, in dispatch
    return super(LoginRequiredMixin, self).dispatch(request, *args, **kwargs)
  File "/Users/VANXV/.virtualenvs/zss322/lib/python3.6/site-packages/django/views/generic/base.py", line 88, in dispatch
    return handler(request, *args, **kwargs)
  File "/Users/VANXV/PycharmProjects/zss/cryapp/views.py", line 86, in post
    savecryorder = CryOrder.objects.create(Userid=request.user,ShopId=saveshop, Status='1', GoodId=saveGoods, StartTime=startdatetime, EndTime=endDateTime,  platform=platform, Keywords=keywords,Note=note, Money=request.POST['money'])
  File "/Users/VANXV/.virtualenvs/zss322/lib/python3.6/site-packages/django/db/models/manager.py", line 85, in manager_method
    return getattr(self.get_queryset(), name)(*args, **kwargs)
  File "/Users/VANXV/.virtualenvs/zss322/lib/python3.6/site-packages/django/db/models/query.py", line 397, in create
    obj = self.model(**kwargs)
  File "/Users/VANXV/.virtualenvs/zss322/lib/python3.6/site-packages/django/db/models/base.py", line 537, in __init__
    setattr(self, field.name, rel_obj)
  File "/Users/VANXV/.virtualenvs/zss322/lib/python3.6/site-packages/django/db/models/fields/related_descriptors.py", line 211, in __set__
    self.field.remote_field.model._meta.object_name,
ValueError: Cannot assign "<QuerySet [<Goods: 14374902753>]>": "CryOrder.GoodId" must be a "Goods" instance.
2017-05-19 20:36:43,589 [Thread-9:123145582211072] [django.request:132] [exception:handle_uncaught_exception] [ERROR]- Internal Server Error: /cryapp/GoodIndexAdd/
Traceback (most recent call last):
  File "/Users/VANXV/.virtualenvs/zss322/lib/python3.6/site-packages/django/core/handlers/exception.py", line 42, in inner
    response = get_response(request)
  File "/Users/VANXV/.virtualenvs/zss322/lib/python3.6/site-packages/django/core/handlers/base.py", line 187, in _get_response
    response = self.process_exception_by_middleware(e, request)
  File "/Users/VANXV/.virtualenvs/zss322/lib/python3.6/site-packages/django/core/handlers/base.py", line 185, in _get_response
    response = wrapped_callback(request, *callback_args, **callback_kwargs)
  File "/Users/VANXV/.virtualenvs/zss322/lib/python3.6/site-packages/django/views/generic/base.py", line 68, in view
    return self.dispatch(request, *args, **kwargs)
  File "/Users/VANXV/.virtualenvs/zss322/lib/python3.6/site-packages/django/contrib/auth/mixins.py", line 56, in dispatch
    return super(LoginRequiredMixin, self).dispatch(request, *args, **kwargs)
  File "/Users/VANXV/.virtualenvs/zss322/lib/python3.6/site-packages/django/views/generic/base.py", line 88, in dispatch
    return handler(request, *args, **kwargs)
  File "/Users/VANXV/PycharmProjects/zss/cryapp/views.py", line 86, in post
    savecryorder = CryOrder.objects.create(Userid=request.user,ShopId=saveshop, Status='1', GoodId=saveGoods, StartTime=startdatetime, EndTime=endDateTime,  platform=platform, Keywords=keywords,Note=note, Money=request.POST['money'])
  File "/Users/VANXV/.virtualenvs/zss322/lib/python3.6/site-packages/django/db/models/manager.py", line 85, in manager_method
    return getattr(self.get_queryset(), name)(*args, **kwargs)
  File "/Users/VANXV/.virtualenvs/zss322/lib/python3.6/site-packages/django/db/models/query.py", line 397, in create
    obj = self.model(**kwargs)
  File "/Users/VANXV/.virtualenvs/zss322/lib/python3.6/site-packages/django/db/models/base.py", line 537, in __init__
    setattr(self, field.name, rel_obj)
  File "/Users/VANXV/.virtualenvs/zss322/lib/python3.6/site-packages/django/db/models/fields/related_descriptors.py", line 211, in __set__
    self.field.remote_field.model._meta.object_name,
ValueError: Cannot assign "<QuerySet [<Goods: 14374902753>]>": "CryOrder.GoodId" must be a "Goods" instance.
2017-05-20 11:14:31,169 [Thread-31:123145583820800] [django.request:152] [base:get_response] [WARNING]- Not Found: /favicon.ico
2017-05-25 13:12:41,349 [Thread-18:123145567031296] [django.request:152] [base:get_response] [WARNING]- Not Found: /favicon.ico
2017-05-25 13:24:24,269 [Thread-61:123145567031296] [django.request:132] [exception:handle_uncaught_exception] [ERROR]- Internal Server Error: /cryapp/GoodIndexAdd/
Traceback (most recent call last):
  File "/Users/VANXV/.virtualenvs/zss322/lib/python3.6/site-packages/django/core/handlers/exception.py", line 42, in inner
    response = get_response(request)
  File "/Users/VANXV/.virtualenvs/zss322/lib/python3.6/site-packages/django/core/handlers/base.py", line 187, in _get_response
    response = self.process_exception_by_middleware(e, request)
  File "/Users/VANXV/.virtualenvs/zss322/lib/python3.6/site-packages/django/core/handlers/base.py", line 185, in _get_response
    response = wrapped_callback(request, *callback_args, **callback_kwargs)
  File "/Users/VANXV/.virtualenvs/zss322/lib/python3.6/site-packages/django/views/generic/base.py", line 68, in view
    return self.dispatch(request, *args, **kwargs)
  File "/Users/VANXV/.virtualenvs/zss322/lib/python3.6/site-packages/django/contrib/auth/mixins.py", line 56, in dispatch
    return super(LoginRequiredMixin, self).dispatch(request, *args, **kwargs)
  File "/Users/VANXV/.virtualenvs/zss322/lib/python3.6/site-packages/django/views/generic/base.py", line 88, in dispatch
    return handler(request, *args, **kwargs)
  File "/Users/VANXV/PycharmProjects/zss/cryapp/views.py", line 86, in post
    savecryorder = CryOrder.objects.create(Userid=request.user,ShopId=saveshop, Status='1', GoodId=saveGoods, StartTime=startdatetime, EndTime=endDateTime,  platform=platform, Keywords=keywords,Note=note, Money=request.POST['money'])
  File "/Users/VANXV/.virtualenvs/zss322/lib/python3.6/site-packages/django/db/models/manager.py", line 85, in manager_method
    return getattr(self.get_queryset(), name)(*args, **kwargs)
  File "/Users/VANXV/.virtualenvs/zss322/lib/python3.6/site-packages/django/db/models/query.py", line 397, in create
    obj = self.model(**kwargs)
  File "/Users/VANXV/.virtualenvs/zss322/lib/python3.6/site-packages/django/db/models/base.py", line 537, in __init__
    setattr(self, field.name, rel_obj)
  File "/Users/VANXV/.virtualenvs/zss322/lib/python3.6/site-packages/django/db/models/fields/related_descriptors.py", line 211, in __set__
    self.field.remote_field.model._meta.object_name,
ValueError: Cannot assign "<QuerySet [<Goods: 14374902753>]>": "CryOrder.GoodId" must be a "Goods" instance.
2017-05-25 13:24:43,753 [Thread-68:123145567031296] [django.request:132] [exception:handle_uncaught_exception] [ERROR]- Internal Server Error: /cryapp/GoodIndexAdd/
Traceback (most recent call last):
  File "/Users/VANXV/.virtualenvs/zss322/lib/python3.6/site-packages/django/core/handlers/exception.py", line 42, in inner
    response = get_response(request)
  File "/Users/VANXV/.virtualenvs/zss322/lib/python3.6/site-packages/django/core/handlers/base.py", line 187, in _get_response
    response = self.process_exception_by_middleware(e, request)
  File "/Users/VANXV/.virtualenvs/zss322/lib/python3.6/site-packages/django/core/handlers/base.py", line 185, in _get_response
    response = wrapped_callback(request, *callback_args, **callback_kwargs)
  File "/Users/VANXV/.virtualenvs/zss322/lib/python3.6/site-packages/django/views/generic/base.py", line 68, in view
    return self.dispatch(request, *args, **kwargs)
  File "/Users/VANXV/.virtualenvs/zss322/lib/python3.6/site-packages/django/contrib/auth/mixins.py", line 56, in dispatch
    return super(LoginRequiredMixin, self).dispatch(request, *args, **kwargs)
  File "/Users/VANXV/.virtualenvs/zss322/lib/python3.6/site-packages/django/views/generic/base.py", line 88, in dispatch
    return handler(request, *args, **kwargs)
  File "/Users/VANXV/PycharmProjects/zss/cryapp/views.py", line 86, in post
    savecryorder = CryOrder.objects.create(Userid=request.user,ShopId=saveshop, Status='1', GoodId=saveGoods, StartTime=startdatetime, EndTime=endDateTime,  platform=platform, Keywords=keywords,Note=note, Money=request.POST['money'])
  File "/Users/VANXV/.virtualenvs/zss322/lib/python3.6/site-packages/django/db/models/manager.py", line 85, in manager_method
    return getattr(self.get_queryset(), name)(*args, **kwargs)
  File "/Users/VANXV/.virtualenvs/zss322/lib/python3.6/site-packages/django/db/models/query.py", line 397, in create
    obj = self.model(**kwargs)
  File "/Users/VANXV/.virtualenvs/zss322/lib/python3.6/site-packages/django/db/models/base.py", line 537, in __init__
    setattr(self, field.name, rel_obj)
  File "/Users/VANXV/.virtualenvs/zss322/lib/python3.6/site-packages/django/db/models/fields/related_descriptors.py", line 211, in __set__
    self.field.remote_field.model._meta.object_name,
ValueError: Cannot assign "<QuerySet [<Goods: 14374902753>]>": "CryOrder.GoodId" must be a "Goods" instance.
2017-05-25 13:34:08,304 [Thread-8:123145417691136] [django.request:132] [exception:handle_uncaught_exception] [ERROR]- Internal Server Error: /cryapp/GoodIndexAdd/
Traceback (most recent call last):
  File "/Users/VANXV/.virtualenvs/zss322/lib/python3.6/site-packages/django/core/handlers/exception.py", line 42, in inner
    response = get_response(request)
  File "/Users/VANXV/.virtualenvs/zss322/lib/python3.6/site-packages/django/core/handlers/base.py", line 187, in _get_response
    response = self.process_exception_by_middleware(e, request)
  File "/Users/VANXV/.virtualenvs/zss322/lib/python3.6/site-packages/django/core/handlers/base.py", line 185, in _get_response
    response = wrapped_callback(request, *callback_args, **callback_kwargs)
  File "/Users/VANXV/.virtualenvs/zss322/lib/python3.6/site-packages/django/views/generic/base.py", line 68, in view
    return self.dispatch(request, *args, **kwargs)
  File "/Users/VANXV/.virtualenvs/zss322/lib/python3.6/site-packages/django/contrib/auth/mixins.py", line 56, in dispatch
    return super(LoginRequiredMixin, self).dispatch(request, *args, **kwargs)
  File "/Users/VANXV/.virtualenvs/zss322/lib/python3.6/site-packages/django/views/generic/base.py", line 88, in dispatch
    return handler(request, *args, **kwargs)
  File "/Users/VANXV/PycharmProjects/zss/cryapp/views.py", line 86, in post
    savecryorder = CryOrder.objects.create(Userid=request.user,ShopId=saveshop, Status='1', GoodId=saveGoods, StartTime=startdatetime, EndTime=endDateTime,  platform=platform, Keywords=keywords,Note=note, Money=request.POST['money'])
  File "/Users/VANXV/.virtualenvs/zss322/lib/python3.6/site-packages/django/db/models/manager.py", line 85, in manager_method
    return getattr(self.get_queryset(), name)(*args, **kwargs)
  File "/Users/VANXV/.virtualenvs/zss322/lib/python3.6/site-packages/django/db/models/query.py", line 397, in create
    obj = self.model(**kwargs)
  File "/Users/VANXV/.virtualenvs/zss322/lib/python3.6/site-packages/django/db/models/base.py", line 537, in __init__
    setattr(self, field.name, rel_obj)
  File "/Users/VANXV/.virtualenvs/zss322/lib/python3.6/site-packages/django/db/models/fields/related_descriptors.py", line 211, in __set__
    self.field.remote_field.model._meta.object_name,
ValueError: Cannot assign "<QuerySet [<Goods: 14374902753>]>": "CryOrder.GoodId" must be a "Goods" instance.
2017-05-25 19:17:59,227 [Thread-13:123145463152640] [django.request:132] [exception:handle_uncaught_exception] [ERROR]- Internal Server Error: /login
Traceback (most recent call last):
  File "/Users/VANXV/.virtualenvs/zss322/lib/python3.6/site-packages/django/core/handlers/exception.py", line 42, in inner
    response = get_response(request)
  File "/Users/VANXV/.virtualenvs/zss322/lib/python3.6/site-packages/django/utils/deprecation.py", line 134, in __call__
    response = self.process_request(request)
  File "/Users/VANXV/.virtualenvs/zss322/lib/python3.6/site-packages/django/middleware/common.py", line 63, in process_request
    path = self.get_full_path_with_slash(request)
  File "/Users/VANXV/.virtualenvs/zss322/lib/python3.6/site-packages/django/middleware/common.py", line 101, in get_full_path_with_slash
    'url': request.get_host() + new_path,
RuntimeError: You called this URL via POST, but the URL doesn't end in a slash and you have APPEND_SLASH set. Django can't redirect to the slash URL while maintaining POST data. Change your form to point to 127.0.0.1:8000/login/ (note the trailing slash), or set APPEND_SLASH=False in your Django settings.
2017-05-25 19:18:44,323 [Thread-14:123145463152640] [django.request:132] [exception:handle_uncaught_exception] [ERROR]- Internal Server Error: /login
Traceback (most recent call last):
  File "/Users/VANXV/.virtualenvs/zss322/lib/python3.6/site-packages/django/core/handlers/exception.py", line 42, in inner
    response = get_response(request)
  File "/Users/VANXV/.virtualenvs/zss322/lib/python3.6/site-packages/django/utils/deprecation.py", line 134, in __call__
    response = self.process_request(request)
  File "/Users/VANXV/.virtualenvs/zss322/lib/python3.6/site-packages/django/middleware/common.py", line 63, in process_request
    path = self.get_full_path_with_slash(request)
  File "/Users/VANXV/.virtualenvs/zss322/lib/python3.6/site-packages/django/middleware/common.py", line 101, in get_full_path_with_slash
    'url': request.get_host() + new_path,
RuntimeError: You called this URL via POST, but the URL doesn't end in a slash and you have APPEND_SLASH set. Django can't redirect to the slash URL while maintaining POST data. Change your form to point to 127.0.0.1:8000/login/ (note the trailing slash), or set APPEND_SLASH=False in your Django settings.
2017-05-25 20:18:58,260 [Thread-2:123145532260352] [django.request:152] [base:get_response] [WARNING]- Not Found: /
2017-05-25 20:19:00,093 [Thread-3:123145537515520] [django.request:152] [base:get_response] [WARNING]- Not Found: /favicon.ico
2017-05-25 20:19:02,739 [Thread-4:123145542770688] [django.request:152] [base:get_response] [WARNING]- Not Found: /api-auth/
2017-05-25 20:19:16,152 [Thread-10:123145531723776] [django.request:152] [base:get_response] [WARNING]- Not Found: /api-auth/
2017-05-25 20:19:24,665 [Thread-11:123145536978944] [django.request:152] [base:get_response] [WARNING]- Not Found: /good/
2017-05-25 20:19:32,046 [Thread-14:123145531723776] [django.request:152] [base:get_response] [WARNING]- Not Found: /good/api-auth/
2017-05-25 20:48:39,826 [Thread-2:123145542094848] [django.request:152] [base:get_response] [WARNING]- Not Found: /
2017-05-25 20:49:30,632 [Thread-11:123145503981568] [django.request:132] [exception:handle_uncaught_exception] [ERROR]- Internal Server Error: /router/users/
Traceback (most recent call last):
  File "/Users/VANXV/.virtualenvs/zss322/lib/python3.6/site-packages/django/core/handlers/exception.py", line 42, in inner
    response = get_response(request)
  File "/Users/VANXV/.virtualenvs/zss322/lib/python3.6/site-packages/django/core/handlers/base.py", line 187, in _get_response
    response = self.process_exception_by_middleware(e, request)
  File "/Users/VANXV/.virtualenvs/zss322/lib/python3.6/site-packages/django/core/handlers/base.py", line 185, in _get_response
    response = wrapped_callback(request, *callback_args, **callback_kwargs)
  File "/Users/VANXV/.virtualenvs/zss322/lib/python3.6/site-packages/django/views/decorators/csrf.py", line 58, in wrapped_view
    return view_func(*args, **kwargs)
  File "/Users/VANXV/PycharmProjects/zss/rest_framework/viewsets.py", line 86, in view
    return self.dispatch(request, *args, **kwargs)
  File "/Users/VANXV/PycharmProjects/zss/rest_framework/views.py", line 489, in dispatch
    response = self.handle_exception(exc)
  File "/Users/VANXV/PycharmProjects/zss/rest_framework/views.py", line 449, in handle_exception
    self.raise_uncaught_exception(exc)
  File "/Users/VANXV/PycharmProjects/zss/rest_framework/views.py", line 486, in dispatch
    response = handler(request, *args, **kwargs)
  File "/Users/VANXV/PycharmProjects/zss/rest_framework/mixins.py", line 48, in list
    return Response(serializer.data)
  File "/Users/VANXV/PycharmProjects/zss/rest_framework/serializers.py", line 739, in data
    ret = super(ListSerializer, self).data
  File "/Users/VANXV/PycharmProjects/zss/rest_framework/serializers.py", line 263, in data
    self._data = self.to_representation(self.instance)
  File "/Users/VANXV/PycharmProjects/zss/rest_framework/serializers.py", line 657, in to_representation
    self.child.to_representation(item) for item in iterable
  File "/Users/VANXV/PycharmProjects/zss/rest_framework/serializers.py", line 657, in <listcomp>
    self.child.to_representation(item) for item in iterable
  File "/Users/VANXV/PycharmProjects/zss/rest_framework/serializers.py", line 484, in to_representation
    fields = self._readable_fields
  File "/Users/VANXV/.virtualenvs/zss322/lib/python3.6/site-packages/django/utils/functional.py", line 35, in __get__
    res = instance.__dict__[self.name] = self.func(instance)
  File "/Users/VANXV/PycharmProjects/zss/rest_framework/serializers.py", line 378, in _readable_fields
    field for field in self.fields.values()
  File "/Users/VANXV/PycharmProjects/zss/rest_framework/serializers.py", line 364, in fields
    for key, value in self.get_fields().items():
  File "/Users/VANXV/PycharmProjects/zss/rest_framework/serializers.py", line 993, in get_fields
    info = model_meta.get_field_info(model)
  File "/Users/VANXV/PycharmProjects/zss/rest_framework/utils/model_meta.py", line 41, in get_field_info
    forward_relations = _get_forward_relationships(opts)
  File "/Users/VANXV/PycharmProjects/zss/rest_framework/utils/model_meta.py", line 98, in _get_forward_relationships
    not get_remote_field(field).through._meta.auto_created
AttributeError: 'NoneType' object has no attribute '_meta'
